Workbook
Name 采光: 定价因子!$D$45:$D$50
Name 床型: 定价因子!$D$52:$D$57
Name 地铁站步行时间: 定价因子!#REF!
Name 电梯房楼层: 定价因子!$D$29:$D$37
Name 公区步行距离: 定价因子!$D$2:$D$6
Name 功能: 定价因子!$D$39:$D$44
Name 户型格局: 定价因子!#REF!
Name 楼栋外观: 定价因子!#REF!
Name 楼梯房楼层: 定价因子!$D$19:$D$28
Name 套内空间: 定价因子!$D$9:$D$13
Name 梯户比: 定价因子!#REF!
Name 阳台: 定价因子!$D$14:$D$18
Name 有无电梯: 定价因子!$D$7:$D$8
Name loft隔断: [2]三类资产目录!$D$8:$F$8

Sheet 更新日志
B2: 版本号 | C2: 更新日期 | D2: 主要更新内容 | E2: 决议方式 | F2: 启用时间
B3: v1.0 | C3: 44036 | D3: 1. 创建了xlsx格式的模型，便于过程数据留存 | F3: 44039
B4: v1.01 | C4: 44056 | D4: 1. 优化了【楼栋公区距离】因子下的调价系数，使公区距离的影响力扩大，更符合市场需求； 2. 新增了定价模型的【更新日志】 | E4: 公寓例会 | F4: 44056
B5: v1.10 | C5: 44131 | D5: 1. 对各个格局的【套内空间】分档明确面积范围； 2. 【地铁站距离】测量方式改为步行时长（百度地图）； 3. 深化完善【户型】【功能】【采光】等因子各分档的标准描述，减小主观误差； | E5: 定价小组会议 | F5: 44132
B6: v1.11 | C6: 44281 | D6: 1. 更新了两个项目的基准价：元芬上早1468.41元，创业花园1763元，以及各个格局的基准价； 2. 删除“高架床/窄床开间”格局，使格局类型与实际业务名词体系一致，新增【床型】因子，用于描述不同床型对定价的影响； 3. 调整了【采光】【地铁站距离】【有无电梯】【楼层】【功能】因子的分档和系数； 4. 删除了【公交站距离】【噪音】【污染】【视野】等极少使用或影响力极小的因子； 5. 深化完善各个因子各分档的标准描述； | F6: 44287
B7: V1.12 | C7: 44670 | D7: 1.更新采光因素量化标准，并增加采光因素填写sheet，需填写房间窗户数量，根据楼间距填写遮挡信息 2.增加审批条件，整体均价≥模型均价，实际定价在模型价格的-5%~15%之间 | F7: 44670
B8: V2.2 | C8: 45127 | D8: 1.将很狭小的折价从0.91修正为0.9； 2.将较宽敞的溢价由1.05提高到1.06，很宽敞溢价由1.09提高到1.10； 3.将楼梯一层的折价由0.9，提高到0.91；将电梯一层的折价由0.85，提高到0.87； | F8: 45127

Sheet 定价因子
B1: 序号 | C1: 定价因子 | D1: 分档 | E1: 数列 | F1: 调价倍数 | G1: 备注 | L1: 项目基准价 | M1: 1449.8
A2: 基准格局定价因子 | B2: 1 | C2: 区位 | D2: 交通很便利 | E2: =$C$2&D2 -> 区位交通很便利 | F2: 1.04 | G2: 距离中心楼栋步行300米以上，且为方向交通更便利，如更靠近地铁，更靠近主干道 | I2: =J2*#REF!-J2 -> #REF! | J2: 1350 | L2: 基准格局 | M2: 套均价
D3: 交通较便利 | E3: =$C$2&D3 -> 区位交通较便利 | F3: 1.02 | G3: 距离中心楼栋步行150米以上，且为方向交通更便利，如更靠近地铁，更靠近主干道 | I3: =J3*#REF!-J3 -> #REF! | J3: 1350 | K3: 1 | L3: 开间 | M3: =$M$1*K3 -> 1449.8
D4: 中心位置 | E4: =$C$2&D4 -> 区位中心位置 | F4: 1 | G4: 在中心楼栋步行半径150米的位置范围内 | I4: =J4*F2-J4 -> 54 | J4: 1350 | K4: 1.5 | L4: 一居室 | M4: 2219.7
D5: 交通较不便 | E5: =$C$2&D5 -> 区位交通较不便 | F5: 0.98 | G5: 距离中心楼栋步行150米以上，且为方向交通更不便，如更远离地铁，距离村口位置更远 | I5: =J5*F3-J5 -> 27 | J5: 1350 | K5: 2 | L5: 二居室 | M5: =$M$1*K5 -> 2899.6
D6: 交通很不便 | E6: =$C$2&D6 -> 区位交通很不便 | F6: 0.96 | G6: 距离中心楼栋步行300米以上，且为方向交通更不便，如更远离地铁，距离村口位置更远 | I6: 100 | J6: 1350 | K6: 1 | L6: 轻复式 | M6: =$M$1*K6 -> 1449.8
B7: 2 | C7: 有无电梯 | D7: 有 | E7: =$C$7&D7 -> 有无电梯有 | F7: 1.05 | G7: 只比较楼梯4F和电梯4F | I7: 80 | J7: 1350 | K7: 1 | L7: 二人宿舍 | M7: =$M$1*K7 -> 1449.8
D8: 无 | E8: =$C$7&D8 -> 有无电梯无 | F8: 1 | I8: =J8*F6-J8 -> -54 | J8: 1350 | K8: 1.5 | L8: 四人宿舍 | M8: =$M$1*K8 -> 2174.7
A9: 房间定价因子 | B9: 1 | C9: 套内空间 | D9: 很宽敞 | E9: =$C$9&D9 -> 套内空间很宽敞 | F9: 1.1 | G9: 权重：客厅>卧室>＞卫生间/洗漱区； 空间为住户实际使用感知的空间，如：（1）裸露地板的面积（2）床周边通行宽度（3）高架床、LOFT利用了立体空间，套内面积狭小但可能套内空间适中 | I9: =J9*F7-J9 -> 0 | K9: 2 | L9: 六人宿舍 | M9: =$M$1*K9 -> 2899.6
D10: 较宽敞 | E10: =$C$9&D10 -> 套内空间较宽敞 | F10: 1.06 | I10: =J10*F8-J10 -> 0 | K10: 2 | L10: 八人宿舍 | M10: =$M$1*K10 -> 2899.6
D11: 适中 | E11: =$C$9&D11 -> 套内空间适中 | F11: 1 | I11: =J11*#REF!-J11 -> #REF! | K11: 2 | L11: 二居轻复式 | M11: =$M$1*K11 -> 2899.6
D12: 较狭小 | E12: =$C$9&D12 -> 套内空间较狭小 | F12: 0.95 | I12: =J12*#REF!-J12 -> #REF!
D13: 很狭小 | E13: =$C$9&D13 -> 套内空间很狭小 | F13: 0.9 | I13: =J13*#REF!-J13 -> #REF!
B14: 3 | C14: 阳台 | I14: =J14*#REF!-J14 -> #REF!
D16: 有 | E16: =$C$14&D16 -> 阳台有 | F16: 1.07 | K16: 套内空间类型 | L16: 高架床/窄床 | M16: 正常开间 | N16: 正常一居室 | O16: 两居室
I17: =J17*F9-J17 -> 135 | J17: 1350 | K17: 很宽敞 | L17: >18 | M17: >20㎡ | N17: >28㎡ | O17: >45㎡
D18: 无 | E18: =$C$14&D18 -> 阳台无 | F18: 1 | I18: =J18*F10-J18 -> 81 | J18: 1350 | K18: 较宽敞 | L18: 15-18㎡ | M18: 17-20㎡ | N18: 26-28㎡ | O18: 40-45㎡
B19: 4 | C19: 楼梯房楼层 | D19: 无 | E19: =$C$19&D19 -> 楼梯房楼层无 | F19: 1 | G19: 不考虑采光和视野的差异 | I19: =J19*F11-J19 -> 0 | J19: 1350 | K19: 适中 | L19: 11-15㎡ | M19: 13-17㎡ | N19: 23-26㎡ | O19: 35-40㎡
D20: 1F | E20: =$C$19&D20 -> 楼梯房楼层1F | F20: 0.91 | I20: =J20*F12-J20 -> -67.5 | J20: 1350 | K20: 较狭小 | L20: 9-11㎡ | M20: 10-13㎡ | N20: 20-23㎡ | O20: 30-35㎡
D21: 2F | E21: =$C$19&D21 -> 楼梯房楼层2F | F21: 1.02 | I21: =J21*F13-J21 -> -135 | J21: 1350 | K21: 很狭小 | L21: <9㎡ | M21: <10㎡ | N21: <20㎡ | O21: <30㎡
D22: 3F | E22: =$C$19&D22 -> 楼梯房楼层3F | F22: 1.01 | I22: =J22*#REF!-J22 -> #REF! | J22: 1350
D23: 4F | E23: =$C$19&D23 -> 楼梯房楼层4F | F23: 1 | I23: =J23*#REF!-J23 -> #REF! | J23: 1350
D24: 5F | E24: =$C$19&D24 -> 楼梯房楼层5F | F24: 0.99 | I24: =J24*#REF!-J24 -> #REF! | J24: 1350
D25: 6F | E25: =$C$19&D25 -> 楼梯房楼层6F | F25: 0.98 | I25: =J25*#REF!-J25 -> #REF! | J25: 1350
D26: 7F | E26: =$C$19&D26 -> 楼梯房楼层7F | F26: 0.96 | I26: =J26*#REF!-J26 -> #REF! | J26: 1350
D27: 8F | E27: =$C$19&D27 -> 楼梯房楼层8F | F27: 0.93 | I27: =J27*F14-J27 -> -1350 | J27: 1350
D28: 9F | E28: =$C$19&D28 -> 楼梯房楼层9F | F28: 0.9 | I28: =J28*F15-J28 -> -1350 | J28: 1350
B29: 5 | C29: 电梯房楼层 | D29: 无 | E29: =$C$29&D29 -> 电梯房楼层无 | F29: 1 | I29: =J29*F16-J29 -> 94.5 | J29: 1350
D30: 1F | E30: =$C$29&D30 -> 电梯房楼层1F | F30: 0.87 | G30: 不考虑采光和视野的差异
D31: 2-3F | E31: =$C$29&D31 -> 电梯房楼层2-3F | F31: 0.99 | I31: =J31*F18-J31 -> 0
D32: 4F | E32: =$C$29&D32 -> 电梯房楼层4F | F32: 1 | I32: =1325*F19-1325 -> 0
D33: 5-6F | E33: =$C$29&D33 -> 电梯房楼层5-6F | F33: 1.01
D34: 7-8F | E34: =$C$29&D34 -> 电梯房楼层7-8F | F34: 1.02 | I34: =1325*F21-1325 -> 26.5
D35: 9-10F | E35: =$C$29&D35 -> 电梯房楼层9-10F | F35: 1.03 | I35: =1325*F22-1325 -> 13.25
D36: 11-12F | E36: =$C$29&D36 -> 电梯房楼层11-12F | F36: 1.04 | I36: =1325*F23-1325 -> 0
D37: 13以上F | E37: =$C$29&D37 -> 电梯房楼层13以上F | F37: 1.05 | I37: =1325*F24-1325 -> -13.25
B38: 6 | C38: 功能配置（开间） | D38: 缺失 | E38: 缺失书桌和操作台 | F38: 0.93
D39: 缺失（书桌） | E39: =$C$38&D39 -> 功能配置（开间）缺失（书桌） | F39: 0.98 | I39: =1325*F25-1325 -> -26.5
D40: 缺失（操作台） | E40: =$C$38&D40 -> 功能配置（开间）缺失（操作台） | F40: 0.96 | I40: =1325*F26-1325 -> -53
D41: 适中 | E41: =$C$38&D41 -> 功能配置（开间）适中 | F41: 1 | I41: =1325*F27-1325 -> -92.75
...

Sheet 【1】基本信息&审核标准
B2: 小区（村） | C2: 福永一队 | D2: 楼栋号 | E2: 6-6栋
B3: 楼栋基本画像 | C3: 电梯 | D3: 屋面晾晒区 | E3: 格局 | F3: 公寓楼层 | G3: 总销售单元数 | H3: 标准层单元数 | I3: 开间均价 | J3: 一居均价 | K3: 单元均价 | L3: 标准层面积 | M3: 公寓面积
C4: 无 | D4: 是 | E4: 开间&一居室 | F4: 7 | G4: 62 | H4: 9 | I4: =AVERAGEIF('【3-2】营销中心填-房间模型价 '!D:D,"开间",'【3-2】营销中心填-房间模型价 '!U:U) -> 1149.1818 | J4: =AVERAGEIF('【3-2】营销中心填-房间模型价 '!D:D,"一居室",'【3-2】营销中心填-房间模型价 '!U:U) -> 1993.9583 | K4: =SUMIF('【3-2】营销中心填-房间模型价 '!A:A,E2,'【3-2】营销中心填-房间模型价 '!U:U)/G4 -> 1383.5161 | L4: 162 | M4: 1347.5
B7: 审批标准
B8: 成本线指标 | C8: 楼栋成本线 | D8: 收楼成本坪效 | E8: 成本标准坪效 | F8: 定价坪效 | G8: 收楼溢价率 | H8: 成本溢价率 | I8: check
D9: 44.53 | E9: =(D9+18)/0.9 -> 69.477778 | F9: =SUMIF('【3-2】营销中心填-房间模型价 '!A:A,E2,'【3-2】营销中心填-房间模型价 '!U:U)/M4 -> 63.657143 | G9: =F9/D9 -> 1.4295339 | H9: =F9/E9 -> 0.91622307 | I9: =IF(H9<1,"不通过","通过") -> 不通过
C11: 村成本线 | D11: 收楼成本坪效 | E11: 成本标准坪效 | F11: 项目整体坪效 | G11: 收楼溢价率 | H11: 成本溢价率 | I11: check
D12: 44.53 | E12: =(D12+18)/0.9 -> 69.477778 | F12: =(VLOOKUP(C2,piovt_各村均价!B:E,4,)*VLOOKUP(C2,piovt_各村均价!B:G,6,0)+F9*M4)/(M4+VLOOKUP(C2,piovt_各村均价!B:G,6,0)) -> #N/A | G12: =F12/D12 -> #N/A | H12: =F12/E12 -> #N/A | I12: =IF(H12<1.05,"不通过","通过") -> #N/A
B14: 竞争线指标 | C14: 楼栋竞争线 | D14: 模型户型均价规律 = 定价户型均价规律 | G14: check
D16: 是 | G16: =IF(D16="是","通过","不通过") -> 通过
C18: 村竞争线 | D18: 项目 | E18: 标签属性 | J18: 挂牌均价 | K18: 签约均价 | L18: 本楼栋同标签定价均价 | M18: check
B24: 模型线指标 | C24: 房间模型线 | D24: 房间偏差最小值 | E24: 房间偏差最大值 | F24: check
D25: =MIN('【3-2】营销中心填-房间模型价 '!X:X) -> -0.21045065 | E25: =MAX('【3-2】营销中心填-房间模型价 '!X:X) -> 0.041538964 | F25: =IF(OR(D25<-10%,E25>10%),"不通过","通过") -> 不通过
C28: 楼栋模型线 | D28: 模型均价 | E28: 定价均价 | F28: check
D29: =AVERAGE('【3-2】营销中心填-房间模型价 '!T:T) -> 1601.9211 | E29: =AVERAGE('【3-2】营销中心填-房间模型价 '!U:U) -> 1504.8772 | F29: =E29/D29 -> 0.93942031

Sheet 【1】楼栋基本信息
B2: 楼栋号： | C2: A28栋
B3: 房源基本画像 | C3: 电梯 | D3: 公区 | E3: 格局
C4: 无 | D4: 无 | E4: 开间&一居室
B6: 公寓楼层 | C6: 总销售单元数 | D6: 标准层单元数 | E6: 开间均价 | F6: 一居均价 | G6: 单元均价 | H6: 标准层面积 | I6: 公寓面积 | J6: 模型均价
B7: 5 | C7: 34 | D7: 7.5 | E7: =AVERAGEIF('【3-2】营销中心填-房间模型价 '!D:D,"开间",'【3-2】营销中心填-房间模型价 '!U:U) -> 1149.1818 | F7: =AVERAGEIF('【3-2】营销中心填-房间模型价 '!D:D,"一居室",'【3-2】营销中心填-房间模型价 '!U:U) -> 1993.9583 | G7: 1681.0588 | H7: 135.73 | I7: 662 | J7: =SUMIF('【3-2】营销中心填-房间模型价 '!A:A,C2,'【3-2】营销中心填-房间模型价 '!T:T)/C7 -> 0
C9: 收楼-楼梯（元/㎡） | D9: 收楼-电梯(元/㎡） | E9: 成本坪效 （含建设按出租率96%） | F9: 定价坪效 | G9: 收楼溢价率 | H9: 成本溢价率
B10: 坪效 | C10: 45 | D10: 55 | E10: =(C10+21)/0.96 -> 68.75 | F10: =SUMIF('【3-2】营销中心填-房间模型价 '!A:A,C2,'【3-2】营销中心填-房间模型价 '!U:U)/I7 -> 0 | G10: =F10/C10 -> 0 | H10: =F10/E10 -> 0
B11: 备注 | C11: 成本坪效=（收入成本+建设成本）/ 96%
B12: 项目 | C12: 属性 | G12: 挂牌价 | H12: 同房型对比
B13: 元芬村 | C13: 10-15平 | D13: 标配 | E13: 无电梯 | F13: 无阳台 | G13: 1533 | H13: =E7/G13 -> 0.74962937
B14: 元芬村 | C14: 15-20平 | D14: 标配 | E14: 无电梯 | F14: 无阳台 | G14: 1619 | H14: =E7/G14 -> 0.70980965
B15: 元芬村 | C15: 20-25平 | D15: 标配 | E15: 无电梯 | F15: 无阳台 | G15: 2202 | H15: =F7/G15 -> 0.9055215
C21: 成本线 | D21: 单楼栋
D22: 全项目

Sheet 项目基准价
A1: 项目 | B1: 单位 | C1: 数值
A2: 租金成本坪效 | B2: 元/㎡/月 | C2: 46.3
A3: 单元平均面积 | B3: ㎡/单元 | C3: 18.9
A4: 单位面积装修成本 | B4: 元/㎡ | C4: 2500
A5: 装修线性折旧年限 | B5: 年 | C5: 10
A6: 稳定出租率 | B6: % | C6: 0.98
A7: 成本法基准价 | B7: 元/单元/月 | C7: =(C2*C3+C4*C3/C5/12)/C6 -> 1294.7143
A8: 成本法权重 | B8: % | C8: 1
A9: 市场法基准价 | B9: 元/单元/月
A10: 市场法权重 | B10: % | C10: =1-C8 -> 0
A11: 项目基准价 | B11: 元/单元/月 | C11: =C7*C8+C9*C10 -> 1294.7143
C12: 套均价 | D12: 单元均价 | F12: 基准价条件 | G12: 地铁站步行距离 | H12: 公交站步行距离 | I12: 公区步行距离 | J12: 噪音 | K12: 污染 | L12: 4楼有无电梯 | M12: 梯户比 | N12: 楼栋外观 | O12: 套内空间 | P12: 户型 | Q12: 阳台 | R12: 楼梯房楼层 | S12: 功能 | T12: 采光 | U12: 视野
A13: 普通开间基准价 | B13: 元/套 | C13: 1325 | D13: =C13/1 -> 1325 | F13: 分档 | G13: 1~1.5km | H13: <0.5km | I13: 0~0.2km | J13: 无 | K13: 无 | L13: 无 | M13: 5~8 | N13: 适中 | O13: 适中 | P13: 适中 | Q13: 无 | R13: 4楼 | S13: 适中 | T13: 适中 | U13: 适中
A14: 高架床/窄床开间基准价 | B14: 元/套 | C14: 1200 | D14: =C14/1 -> 1200
A15: 普通1居基准价 | B15: 元/套 | C15: 1850 | D15: =C15/1.5 -> 1233.3333
A16: 客厅功能性弱的1居基准价 | B16: 元/套 | C16: 1650 | D16: =C16/1.5 -> 1100
A17: LOFT基准价 | B17: 元/套 | D17: =C17/1.5 -> 0
A18: 2居基准价 | B18: 元/套 | D18: =C18/2 -> 0
A19: 2人间宿舍基准价 | B19: 元/套 | D19: =C19/1 -> 0

Sheet 赋权表
F1: 运营中心 | N1: 营销中心
E2: =MEDIAN(E8:E54) -> #REF! | F2: 地铁站步行距离 | G2: 公交站步行距离 | H2: 公区步行距离 | I2: 噪音 | J2: 污染 | K2: 4楼有无电梯 | L2: 梯户比 | M2: 楼栋外观 | N2: 套内空间 | O2: 户型 | P2: 阳台 | Q2: 楼梯房楼层 | R2: 功能 | S2: 采光 | T2: 视野
B3: 基准条件 | F3: 1~1.5km | G3: <0.5km | H3: 0~0.2km | I3: 无 | J3: 无 | K3: 无 | L3: 5~8 | M3: 适中 | N3: 适中 | O3: 适中 | P3: 无 | Q3: 4楼 | R3: 适中 | S3: 适中 | T3: 适中
B4: 相对优 | F4: 0.5~1km | G4: <0.5km | H4: 0~0.2km | I4: 无 | J4: 无 | K4: 无 | L4: 5~8 | M4: 优 | N4: 较宽敞 | O4: 适中 | P4: 小 | Q4: 4楼 | R4: 充足 | S4: 很好 | T4: 优
B5: 相对差 | E5: 差异率 | F5: 1~1.5km | G5: 0.5~1km | H5: 0.2~0.5km | I5: 中 | J5: 中 | K5: 有 | L5: >8 | M5: 适中 | N5: 适中 | O5: 差 | P5: 无 | Q5: 5楼 | R5: 适中 | S5: 适中 | T5: 适中
B7: V59-406 | C7: 定价租金 | D7: 1419 | F7: 1~1.5km | G7: <0.5km | H7: 0~0.2km | I7: 无 | J7: 无 | K7: 无 | L7: 5~8 | M7: 适中 | N7: 较宽敞 | O7: 适中 | P7: 无 | Q7: 4楼 | R7: 适中 | S7: 较差 | T7: 适中
C8: 模型租金 | D8: =项目基准价!C13*PRODUCT(赋权表!F8:T8) -> #REF! | E8: =D7/D8-1 -> #REF! | F8: =定价因子!#REF! -> #REF! | G8: =定价因子!F58 -> 1 | H8: =定价因子!F6 -> 0.96 | I8: =定价因子!F66 -> 1 | J8: =定价因子!F70 -> 1 | K8: =定价因子!F8 -> 1 | L8: =定价因子!#REF! -> #REF! | M8: =定价因子!#REF! -> #REF! | N8: =定价因子!F10 -> 1.06 | O8: =定价因子!#REF! -> #REF! | P8: =定价因子!F18 -> 1 | Q8: =定价因子!F23 -> 1 | R8: =定价因子!F41 -> 1 | S8: =定价因子!F48 -> 1 | T8: =定价因子!F64 -> 1
B9: N258-305 | C9: 定价租金 | D9: 1469 | F9: >1.5km | G9: <0.5km | H9: 0.2~0.5km | I9: 无 | J9: 无 | K9: 无 | L9: 5~8 | M9: 适中 | N9: 较宽敞 | O9: 适中 | P9: 无 | Q9: 3楼 | R9: 充足 | S9: 好 | T9: 优
C10: 模型租金 | D10: =项目基准价!C13*PRODUCT(赋权表!F10:T10) -> #REF! | E10: =D9/D10-1 -> #REF! | F10: =定价因子!#REF! -> #REF! | G10: =定价因子!F58 -> 1 | H10: =定价因子!#REF! -> #REF! | I10: =I8 -> 1 | J10: =J8 -> 1 | K10: =K8 -> 1 | L10: =L8 -> #REF! | M10: =M8 -> #REF! | N10: =N8 -> 1.06 | O10: =O8 -> #REF! | P10: =P8 -> 1 | Q10: =定价因子!F22 -> 1.01 | R10: =定价因子!F42 -> 1.04 | S10: =定价因子!F46 -> 1.06 | T10: =定价因子!F62 -> 1.045
B11: T78-1404 | C11: 定价租金 | D11: 1470 | F11: 1~1.5km | G11: <0.5km | H11: 楼内 | I11: 无 | J11: 无 | K11: 有 | L11: >8 | M11: 适中 | N11: 适中 | O11: 适中 | P11: 小 | Q11: 14楼 | R11: 适中 | S11: 好 | T11: 适中
C12: 模型租金 | D12: =项目基准价!$C$13*PRODUCT(赋权表!F12:T12) -> #REF! | E12: =D11/D12-1 -> #REF! | F12: =F8 -> #REF! | G12: =G8 -> 1 | H12: =定价因子!F2 -> 1.04 | I12: =I8 -> 1 | J12: =J8 -> 1 | K12: =定价因子!F7 -> 1.05 | L12: =定价因子!#REF! -> #REF! | M12: =M8 -> #REF! | N12: 1 | O12: =O8 -> #REF! | P12: =定价因子!F16 -> 1.07 | Q12: =定价因子!F35 -> 1.03 | R12: =R8 -> 1 | S12: =定价因子!F46 -> 1.06 | T12: =T8 -> 1
B13: V20-410 | C13: 定价租金 | D13: 1509 | F13: 1~1.5km | G13: <0.5km | H13: 0~0.2km | I13: 无 | J13: 无 | K13: 无 | L13: >8 | M13: 适中 | N13: 很宽敞 | O13: 适中 | P13: 无 | Q13: 4楼 | R13: 充足 | S13: 好 | T13: 适中 | U13: =70/1300 -> 0.053846154
C14: 模型租金 | D14: =项目基准价!$C$13*PRODUCT(赋权表!F14:T14) -> #REF! | E14: =D13/D14-1 -> #REF! | F14: =F8 -> #REF! | G14: =G8 -> 1 | H14: =H8 -> 0.96 | I14: =I8 -> 1 | J14: =J8 -> 1 | K14: =K8 -> 1 | L14: =L12 -> #REF! | M14: =M8 -> #REF! | N14: =定价因子!F9 -> 1.1 | O14: =O8 -> #REF! | P14: =P8 -> 1 | Q14: =Q8 -> 1 | R14: =R10 -> 1.04 | S14: =S10 -> 1.06 | T14: =T8 -> 1
B15: V17-105 | C15: 定价租金 | D15: 1519 | F15: 1~1.5km | G15: <0.5km | H15: 0.2~0.5km | I15: 无 | J15: 无 | K15: 无 | L15: 5~8 | M15: 适中 | N15: 较宽敞 | O15: 适中 | P15: 无 | Q15: 1楼 | R15: 适中 | S15: 很差 | T15: 适中
C16: 模型租金 | D16: =项目基准价!$C$15*PRODUCT(赋权表!F16:T16) -> #REF! | E16: =D15/D16-1 -> #REF! | F16: =F14 -> #REF! | G16: =G14 -> 1 | H16: =H10 -> #REF! | I16: =I10 -> 1 | J16: =J10 -> 1 | K16: =K10 -> 1 | L16: =L10 -> #REF! | M16: =M10 -> #REF! | N16: =N10 -> 1.06 | O16: =O10 -> #REF! | P16: =P10 -> 1 | Q16: =定价因子!F30 -> 0.87 | R16: =R8 -> 1 | S16: =定价因子!F49 -> 0.96 | T16: =T8 -> 1
B17: V17-104 | C17: 定价租金 | D17: 1099 | F17: 1~1.5km | G17: <0.5km | H17: 0.2~0.5km | I17: 无 | J17: 无 | K17: 无 | L17: 5~8 | M17: 适中 | N17: 较狭小 | O17: 适中 | P17: 无 | Q17: 1楼 | R17: 适中 | S17: 很差 | T17: 适中
C18: 模型租金 | D18: =项目基准价!$C$13*PRODUCT(赋权表!F18:T18) -> #REF! | E18: =D17/D18-1 -> #REF! | F18: =F16 -> #REF! | G18: =G16 -> 1 | H18: =H16 -> #REF! | I18: =I16 -> 1 | J18: =J16 -> 1 | K18: =K16 -> 1 | L18: =L16 -> #REF! | M18: =M16 -> #REF! | N18: =定价因子!F12 -> 0.95 | O18: =O16 -> #REF! | P18: =P16 -> 1 | Q18: =Q16 -> 0.87 | R18: =R16 -> 1 | S18: =S16 -> 0.96 | T18: =T16 -> 1
B19: X20-1020 | C19: 定价租金 | D19: 2199 | F19: 1~1.5km | G19: <0.5km | H19: >0.5km | I19: 无 | J19: 无 | K19: 有 | L19: >8 | M19: 适中 | N19: 很宽敞 | O19: 适中 | P19: 无 | Q19: 10楼 | R19: 适中 | S19: 好 | T19: 较好
C20: 模型租金 | D20: =项目基准价!$C$15*PRODUCT(赋权表!F20:T20) -> #REF! | E20: =D19/D20-1 -> #REF! | F20: =F18 -> #REF! | G20: =G18 -> 1 | H20: =定价因子!#REF! -> #REF! | I20: =I12 -> 1 | J20: =J12 -> 1 | K20: =K12 -> 1.05 | L20: =L12 -> #REF! | M20: =M12 -> #REF! | N20: =N14 -> 1.1 | O20: =O14 -> #REF! | P20: =P14 -> 1 | Q20: =Q12 -> 1.03 | R20: =R12 -> 1 | S20: =S14 -> 1.06 | T20: =定价因子!F63 -> 1.02
B21: X20-1001 | C21: 定价租金 | D21: 839 | F21: 1~1.5km | G21: <0.5km | H21: >0.5km | I21: 无 | J21: 无 | K21: 有 | L21: >8 | M21: 适中 | N21: 非常狭小 | O21: 适中 | P21: 无 | Q21: 10楼 | R21: 非常缺失 | S21: 好 | T21: 较好
C22: 模型租金 | D22: =项目基准价!$C$14*PRODUCT(赋权表!F22:T22) -> #REF! | E22: =D21/D22-1 -> #REF! | F22: =F20 -> #REF! | G22: =G20 -> 1 | H22: =H20 -> #REF! | I22: =I20 -> 1 | J22: =J20 -> 1 | K22: =K20 -> 1.05 | L22: =L20 -> #REF! | M22: =M20 -> #REF! | N22: 0.86 | O22: =O20 -> #REF! | P22: =P20 -> 1 | Q22: =Q20 -> 1.03 | R22: 0.9 | S22: =S20 -> 1.06 | T22: =T20 -> 1.02
B23: T78-815 | C23: 定价租金 | D23: 1379 | F23: 1~1.5km | G23: <0.5km | H23: 楼内 | I23: 无 | J23: 无 | K23: 有 | L23: >8 | M23: 适中 | N23: 适中 | O23: 适中 | P23: 小 | Q23: 8楼 | R23: 适中 | S23: 好 | T23: 适中
C24: 模型租金 | D24: =项目基准价!$C$14*PRODUCT(赋权表!F24:T24) -> #REF! | E24: =D23/D24-1 -> #REF! | F24: =F12 -> #REF! | G24: =G12 -> 1 | H24: =H12 -> 1.04 | I24: =I12 -> 1 | J24: =J12 -> 1 | K24: =K12 -> 1.05 | L24: =L12 -> #REF! | M24: =M12 -> #REF! | N24: =N12 -> 1 | O24: =O22 -> #REF! | P24: =P12 -> 1.07 | Q24: =定价因子!F34 -> 1.02 | R24: =R12 -> 1 | S24: =S12 -> 1.06 | T24: =T12 -> 1
A25: 高架 | B25: V21-301 | C25: 定价租金 | D25: 1439 | F25: 1~1.5km | G25: <0.5km | H25: 0~0.2km | I25: 无 | J25: 无 | K25: 无 | L25: 5~8 | M25: 适中 | N25: 较宽敞 | O25: 适中 | P25: 超大 | Q25: 3楼 | R25: 适中 | S25: 好 | T25: 适中
C26: 模型租金 | D26: =项目基准价!$C$14*PRODUCT(赋权表!F26:T26) -> #REF! | E26: =D25/D26-1 -> #REF! | F26: =F14 -> #REF! | G26: =G14 -> 1 | H26: =H14 -> 0.96 | I26: =I14 -> 1 | J26: =J14 -> 1 | K26: =K14 -> 1 | L26: =L18 -> #REF! | M26: =M14 -> #REF! | N26: =N16 -> 1.06 | O26: =O16 -> #REF! | P26: =定价因子!F14 -> 0 | Q26: =定价因子!F22 -> 1.01 | R26: =R24 -> 1 | S26: =S24 -> 1.06 | T26: =T24 -> 1
B27: V46-204 | C27: 定价租金 | D27: 1799 | F27: 1~1.5km | G27: <0.5km | H27: 0~0.2km | I27: 无 | J27: 无 | K27: 无 | L27: 5~8 | M27: 优 | N27: 适中 | O27: 适中 | P27: 无 | Q27: 2楼 | R27: 适中 | S27: 适中 | T27: 适中
C28: 模型租金 | D28: =项目基准价!$C$15*PRODUCT(赋权表!F28:T28) -> #REF! | E28: =D27/D28-1 -> #REF! | F28: =F26 -> #REF! | G28: =G26 -> 1 | H28: =H26 -> 0.96 | I28: =I26 -> 1 | J28: =J26 -> 1 | K28: =K26 -> 1 | L28: =L26 -> #REF! | M28: =定价因子!#REF! -> #REF! | N28: =N24 -> 1 | O28: =O24 -> #REF! | P28: =P22 -> 1 | Q28: =定价因子!F21 -> 1.02 | R28: =R26 -> 1 | S28: =定价因子!F47 -> 1.03 | T28: =T26 -> 1
B29: V46-304 | C29: 定价租金 | D29: 1999 | F29: 1~1.5km | G29: <0.5km | H29: 0~0.2km | I29: 无 | J29: 无 | K29: 无 | L29: 5~8 | M29: 优 | N29: 适中 | O29: 适中 | P29: 大 | Q29: 2楼 | R29: 适中 | S29: 适中 | T29: 很好
C30: 模型租金 | D30: =项目基准价!$C$15*PRODUCT(赋权表!F30:T30) -> #REF! | E30: =D29/D30-1 -> #REF! | F30: =F28 -> #REF! | G30: =G28 -> 1 | H30: =H28 -> 0.96 | I30: =I28 -> 1 | J30: =J28 -> 1 | K30: =K28 -> 1 | L30: =L28 -> #REF! | M30: =M28 -> #REF! | ... O30: =O28 -> #REF! | P30: =定价因子!F15 -> 0 | Q30: =Q28 -> 1.02 | R30: =R28 -> 1 | S30: =S28 -> 1.03 | T30: =定价因子!F62 -> 1.045
B31: V17-301 | C31: 定价租金 | D31: 1569 | F31: 1~1.5km | G31: <0.5km | H31: 0.2~0.5km | I31: 无 | J31: 无 | K31: 无 | L31: 5~8 | M31: 适中 | N31: 适中 | O31: 适中 | P31: 大 | Q31: 3楼 | R31: 缺失 | S31: 较差 | T31: 适中
A32: 弱1居 | C32: 模型租金 | D32: =项目基准价!$C$16*PRODUCT(赋权表!F32:T32) -> #REF! | E32: =D31/D32-1 -> #REF! | F32: =F18 -> #REF! | G32: =G18 -> 1 | H32: =H18 -> #REF! | I32: =I18 -> 1 | J32: =J18 -> 1 | K32: =K18 -> 1 | L32: =L18 -> #REF! | M32: =M18 -> #REF! | N32: =N30 -> 1 | O32: =O30 -> #REF! | P32: =P30 -> 0 | Q32: =Q30 -> 1.02 | S32: =S8 -> 1 | T32: =T28 -> 1
B33: T78-1401 | C33: 定价租金 | D33: 2299 | F33: 1~1.5km | G33: <0.5km | H33: 楼内 | I33: 无 | J33: 无 | K33: 有 | L33: >8 | M33: 适中 | N33: 较宽敞 | O33: 适中 | P33: 小 | Q33: 14楼 | R33: 适中 | S33: 好 | T33: 较好
C34: 模型租金 | D34: =项目基准价!$C$15*PRODUCT(赋权表!F34:T34) -> #REF! | E34: =D33/D34-1 -> #REF! | F34: =F24 -> #REF! | G34: =G24 -> 1 | H34: =H24 -> 1.04 | I34: =I24 -> 1 | J34: =J24 -> 1 | K34: =K24 -> 1.05 | L34: =L24 -> #REF! | M34: =M24 -> #REF! | N34: =N26 -> 1.06 | O34: =O26 -> #REF! | P34: =P24 -> 1.07 | Q34: =定价因子!F35 -> 1.03 | R34: =R30 -> 1 | S34: =S10 -> 1.06 | T34: =T20 -> 1.02
A35: 高架 | B35: V46-606 | C35: 定价租金 | D35: 1249 | F35: 1~1.5km | G35: <0.5km | H35: 0~0.2km | I35: 无 | J35: 无 | K35: 无 | L35: 5~8 | M35: 优 | N35: 适中 | O35: 适中 | P35: 无 | Q35: 6楼 | R35: 适中 | S35: 好 | T35: 适中
C36: 模型租金 | D36: =项目基准价!$C$14*PRODUCT(赋权表!F36:T36) -> #REF! | E36: =D35/D36-1 -> #REF! | F36: =F30 -> #REF! | G36: =G30 -> 1 | H36: =H30 -> 0.96 | I36: =I34 -> 1 | J36: =J30 -> 1 | K36: =K30 -> 1 | L36: =L32 -> #REF! | M36: =M30 -> #REF! | N36: =N30 -> 1 | O36: =O34 -> #REF! | P36: =P28 -> 1 | Q36: =定价因子!F25 -> 0.98 | R36: =R34 -> 1 | S36: =S34 -> 1.06 | T36: =T32 -> 1
A37: 高架 | B37: V60-504 | C37: 定价租金 | D37: 1299 | F37: 1~1.5km | G37: <0.5km | H37: 0~0.2km | I37: 无 | J37: 无 | K37: 无 | L37: 5~8 | M37: 适中 | N37: 适中 | O37: 适中 | P37: 无 | Q37: 5楼 | R37: 适中 | S37: 适中 | T37: 适中
C38: 模型租金 | D38: =项目基准价!$C$14*PRODUCT(赋权表!F38:T38) -> #REF! | E38: =D37/D38-1 -> #REF! | F38: =F8 -> #REF! | G38: =G8 -> 1 | H38: =H8 -> 0.96 | I38: =I36 -> 1 | J38: =J8 -> 1 | K38: =K8 -> 1 | L38: =L8 -> #REF! | M38: =M8 -> #REF! | N38: =N36 -> 1 | O38: =O36 -> #REF! | P38: =P36 -> 1 | Q38: =定价因子!F24 -> 0.99 | R38: =R36 -> 1 | S38: =S28 -> 1.03 | T38: =T28 -> 1
B39: V19-505 | C39: 定价租金 | D39: 1239 | F39: 1~1.5km | G39: <0.5km | H39: 0.2~0.5km | I39: 无 | J39: 无 | K39: 无 | L39: 5~8 | M39: 适中 | N39: 适中 | O39: 适中 | P39: 无 | Q39: 5楼 | R39: 充足 | S39: 较差 | T39: 适中
C40: 模型租金 | D40: =项目基准价!$C$13*PRODUCT(赋权表!F40:T40) -> #REF! | E40: =D39/D40-1 -> #REF! | F40: =F32 -> #REF! | G40: =G32 -> 1 | H40: =H32 -> #REF! | I40: =I38 -> 1 | J40: =J32 -> 1 | K40: =K32 -> 1 | L40: =L32 -> #REF! | M40: =M32 -> #REF! | N40: =N38 -> 1 | O40: =O38 -> #REF! | P40: =P38 -> 1 | Q40: =Q38 -> 0.99 | R40: =R14 -> 1.04 | S40: =S32 -> 1 | T40: =T38 -> 1
A41: 弱1居 | B41: V60-303 | C41: 定价租金 | D41: 1699 | F41: 1~1.5km | G41: <0.5km | H41: 0~0.2km | I41: 无 | J41: 无 | K41: 无 | L41: 5~8 | M41: 适中 | N41: 适中 | O41: 适中 | P41: 无 | Q41: 3楼 | R41: 缺失 | S41: 适中 | T41: 适中
...

Sheet 目录
A1: 地铁站步行距离
A2: 公交站步行距离
A3: 公区步行距离
A4: 噪音影响度
A5: 污染
A6: 四楼有无电梯
A7: 梯户比
A8: 楼栋外观
A9: 套内空间
A10: 户型
A11: 阳台
A12: 楼梯房楼层
... A16: 视野

Sheet 【2】运营中心填-楼栋基准格局定价
A1: 楼栋 | B1: 基准格局 | C1: 基准格局基准价 | D1: 区位 | E1: 调价倍数1 | F1: 有无电梯 | G1: 调价倍数3 | H1: 基准格局定价
A2: ='【1】基本信息&审核标准'!$E$2 -> 6-6栋 | B2: 开间 | C2: =VLOOKUP(B2,[3]定价因子!L:M,2,0) -> 1449.8 | D2: 中心位置 | E2: =VLOOKUP(D2,定价因子!$D:$F,3,0) -> 1 | F2: 无 | G2: =VLOOKUP(F2,定价因子!D:F,3,0) -> 1 | H2: =C2*PRODUCT(G2,,E2) -> 1449.8
A3: ='【1】基本信息&审核标准'!$E$2 -> 6-6栋 | B3: 一居室 | C3: =VLOOKUP(B3,[3]定价因子!L:M,2,0) -> 2219.7 | D3: 中心位置 | E3: =VLOOKUP(D3,定价因子!$D:$F,3,0) -> 1 | F3: 无 | G3: =VLOOKUP(F3,定价因子!D:F,3,0) -> 1 | H3: =C3*PRODUCT(G3,,E3) -> 2219.7
C4: =VLOOKUP(B4,定价因子!L:M,2,0) -> #N/A | E4: =VLOOKUP($D$1&D4,定价因子!E:F,2,0) -> #N/A | G4: =VLOOKUP($F$1&F4,定价因子!E:F,2,0) -> #N/A | H4: =C4*PRODUCT(#REF!,#REF!,G4,,#REF!,E4) -> #N/A
C5: =VLOOKUP(B5,定价因子!L:M,2,0) -> #N/A | E5: =VLOOKUP($D$1&D5,定价因子!E:F,2,0) -> #N/A | G5: =VLOOKUP($F$1&F5,定价因子!E:F,2,0) -> #N/A | H5: =C5*PRODUCT(#REF!,#REF!,G5,,#REF!,E5) -> #N/A
C6: =VLOOKUP(B6,定价因子!L:M,2,0) -> #N/A | E6: =VLOOKUP($D$1&D6,定价因子!E:F,2,0) -> #N/A | G6: =VLOOKUP($F$1&F6,定价因子!E:F,2,0) -> #N/A | H6: =C6*PRODUCT(#REF!,#REF!,G6,,#REF!,E6) -> #N/A
C7: =VLOOKUP(B7,定价因子!L:M,2,0) -> #N/A | E7: =VLOOKUP($D$1&D7,定价因子!E:F,2,0) -> #N/A | G7: =VLOOKUP($F$1&F7,定价因子!E:F,2,0) -> #N/A | H7: =C7*PRODUCT(#REF!,#REF!,G7,,#REF!,E7) -> #N/A
C8: =VLOOKUP(B8,定价因子!L:M,2,0) -> #N/A | E8: =VLOOKUP($D$1&D8,定价因子!E:F,2,0) -> #N/A | G8: =VLOOKUP($F$1&F8,定价因子!E:F,2,0) -> #N/A | H8: =C8*PRODUCT(#REF!,#REF!,G8,,#REF!,E8) -> #N/A
C9: =VLOOKUP(B9,定价因子!L:M,2,0) -> #N/A | E9: =VLOOKUP($D$1&D9,定价因子!E:F,2,0) -> #N/A | G9: =VLOOKUP($F$1&F9,定价因子!E:F,2,0) -> #N/A | H9: =C9*PRODUCT(#REF!,#REF!,G9,,#REF!,E9) -> #N/A
C10: =VLOOKUP(B10,定价因子!L:M,2,0) -> #N/A | E10: =VLOOKUP($D$1&D10,定价因子!E:F,2,0) -> #N/A | G10: =VLOOKUP($F$1&F10,定价因子!E:F,2,0) -> #N/A | H10: =C10*PRODUCT(#REF!,#REF!,G10,,#REF!,E10) -> #N/A
C11: =VLOOKUP(B11,定价因子!L:M,2,0) -> #N/A | E11: =VLOOKUP($D$1&D11,定价因子!E:F,2,0) -> #N/A | G11: =VLOOKUP($F$1&F11,定价因子!E:F,2,0) -> #N/A | H11: =C11*PRODUCT(#REF!,#REF!,G11,,#REF!,E11) -> #N/A
C12: =VLOOKUP(B12,定价因子!L:M,2,0) -> #N/A | E12: =VLOOKUP($D$1&D12,定价因子!E:F,2,0) -> #N/A | G12: =VLOOKUP($F$1&F12,定价因子!E:F,2,0) -> #N/A | H12: =C12*PRODUCT(#REF!,#REF!,G12,,#REF!,E12) -> #N/A
C13: =VLOOKUP(B13,定价因子!L:M,2,0) -> #N/A | E13: =VLOOKUP($D$1&D13,定价因子!E:F,2,0) -> #N/A | G13: =VLOOKUP($F$1&F13,定价因子!E:F,2,0) -> #N/A | H13: =C13*PRODUCT(#REF!,#REF!,G13,,#REF!,E13) -> #N/A
C14: =VLOOKUP(B14,定价因子!L:M,2,0) -> #N/A | E14: =VLOOKUP($D$1&D14,定价因子!E:F,2,0) -> #N/A | G14: =VLOOKUP($F$1&F14,定价因子!E:F,2,0) -> #N/A | H14: =C14*PRODUCT(#REF!,#REF!,G14,,#REF!,E14) -> #N/A
C15: =VLOOKUP(B15,定价因子!L:M,2,0) -> #N/A | E15: =VLOOKUP($D$1&D15,定价因子!E:F,2,0) -> #N/A | G15: =VLOOKUP($F$1&F15,定价因子!E:F,2,0) -> #N/A | H15: =C15*PRODUCT(#REF!,#REF!,G15,,#REF!,E15) -> #N/A
... C15172: =VLOOKUP(B15172,定价因子!L:M,2,0) -> #N/A | E15172: =VLOOKUP($D$1&D15172,定价因子!E:F,2,0) -> #N/A | G15172: =VLOOKUP($F$1&F15172,定价因子!E:F,2,0) -> #N/A | H15172: =C15172*PRODUCT(#REF!,#REF!,G15172,,#REF!,E15172) -> #N/A

Sheet 【3-1】营销中心填-采光基本要素
D1: 仅需填写绿色部分，其余部分自动带出
A2: 房间号 | B2: 户型 | C2: 格局 | D2: 房间窗户数量（不含卫生间窗户） | E2: 阳台数量 | F2: 阳台面积（有阳台填写） | G2: 窗户遮挡数量 | H2: 采光判断 | I2: 有无玄关 | L2: 窗户遮挡填写标准
A3: ='【3-2】营销中心填-房间模型价 '!B2 -> 101 | B3: ='【3-2】营销中心填-房间模型价 '!C2 -> 6-6A | C3: =VLOOKUP(A3,'【3-2】营销中心填-房间模型价 '!B:D,3,0) -> 开间 | D3: 1 | E3: 0 | G3: 1 | H3: =IF(C3="开间",IF(D3+E3*2-G3<=0,"1",IF(D3+E3*2-G3<=1,"2",IF(D3+E3*2-G3<=2,"3",IF(D3+E3*2-G3<=3,"4","5")))),IF(D3+E3*2-G3<1.1,"1",IF(D3+E3*2-G3<=2,"2",IF(D3+E3*2-G3<=3,"3",IF(D3+E3*2-G3<=4,"4","5"))))) -> 1 | I3: 无 | L3: 情况 | O3: 填写值
A4: ='【3-2】营销中心填-房间模型价 '!B3 -> 102 | B4: ='【3-2】营销中心填-房间模型价 '!C3 -> 6-6A | C4: =VLOOKUP(A4,'【3-2】营销中心填-房间模型价 '!B:D,3,0) -> 开间 | D4: 1 | E4: 0 | G4: 1 | H4: =IF(C4="开间",IF(D4+E4*2-G4<=0,"1",IF(D4+E4*2-G4<=1,"2",IF(D4+E4*2-G4<=2,"3",IF(D4+E4*2-G4<=3,"4","5")))),IF(D4+E4*2-G4<1.1,"1",IF(D4+E4*2-G4<=2,"2",IF(D4+E4*2-G4<=3,"3",IF(D4+E4*2-G4<=4,"4","5"))))) -> 1 | I4: 无 | L4: 窗户所面对的完全无楼栋或楼间距＞10米 | O4: -1
A5: ='【3-2】营销中心填-房间模型价 '!B4 -> 103 | B5: ='【3-2】营销中心填-房间模型价 '!C4 -> 6-6B | C5: =VLOOKUP(A5,'【3-2】营销中心填-房间模型价 '!B:D,3,0) -> 开间 | D5: 1 | E5: 0 | G5: 1 | H5: =IF(C5="开间",IF(D5+E5*2-G5<=0,"1",IF(D5+E5*2-G5<=1,"2",IF(D5+E5*2-G5<=2,"3",IF(D5+E5*2-G5<=3,"4","5")))),IF(D5+E5*2-G5<1.1,"1",IF(D5+E5*2-G5<=2,"2",IF(D5+E5*2-G5<=3,"3",IF(D5+E5*2-G5<=4,"4","5"))))) -> 1 | I5: 无 | L5: 窗户对面有楼 | M5: 1-4楼窗户所对楼间距＞3米 | O5: 0
A6: ='【3-2】营销中心填-房间模型价 '!B5 -> 104 | B6: ='【3-2】营销中心填-房间模型价 '!C5 -> 6-6C | C6: =VLOOKUP(A6,'【3-2】营销中心填-房间模型价 '!B:D,3,0) -> 开间 | D6: 1 | E6: 0 | G6: 1 | H6: =IF(C6="开间",IF(D6+E6*2-G6<=0,"1",IF(D6+E6*2-G6<=1,"2",IF(D6+E6*2-G6<=2,"3",IF(D6+E6*2-G6<=3,"4","5")))),IF(D6+E6*2-G6<1.1,"1",IF(D6+E6*2-G6<=2,"2",IF(D6+E6*2-G6<=3,"3",IF(D6+E6*2-G6<=4,"4","5"))))) -> 1 | I6: 无 | M6: 4楼以上窗户所对楼间距＞2米 | O6: 0
A7: ='【3-2】营销中心填-房间模型价 '!B6 -> 105 | B7: ='【3-2】营销中心填-房间模型价 '!C6 -> 6-6D | C7: =VLOOKUP(A7,'【3-2】营销中心填-房间模型价 '!B:D,3,0) -> 开间 | D7: 0 | E7: 0 | G7: 0 | H7: =IF(C7="开间",IF(D7+E7*2-G7<=0,"1",IF(D7+E7*2-G7<=1,"2",IF(D7+E7*2-G7<=2,"3",IF(D7+E7*2-G7<=3,"4","5")))),IF(D7+E7*2-G7<1.1,"1",IF(D7+E7*2-G7<=2,"2",IF(D7+E7*2-G7<=3,"3",IF(D7+E7*2-G7<=4,"4","5"))))) -> 1 | I7: 无 | M7: 1-4楼窗户所对楼间距＜3米 | O7: 1*窗户遮挡数量
A8: ='【3-2】营销中心填-房间模型价 '!B7 -> 106 | B8: ='【3-2】营销中心填-房间模型价 '!C7 -> 6-6D | C8: =VLOOKUP(A8,'【3-2】营销中心填-房间模型价 '!B:D,3,0) -> 开间 | D8: 0 | E8: 0 | G8: 0 | H8: =IF(C8="开间",IF(D8+E8*2-G8<=0,"1",IF(D8+E8*2-G8<=1,"2",IF(D8+E8*2-G8<=2,"3",IF(D8+E8*2-G8<=3,"4","5")))),IF(D8+E8*2-G8<1.1,"1",IF(D8+E8*2-G8<=2,"2",IF(D8+E8*2-G8<=3,"3",IF(D8+E8*2-G8<=4,"4","5"))))) -> 1 | I8: 无 | M8: 4楼以上窗户所对楼间距＜2米 | O8: 1*窗户遮挡数量
A9: ='【3-2】营销中心填-房间模型价 '!B8 -> 107 | B9: ='【3-2】营销中心填-房间模型价 '!C8 -> 6-6C | C9: =VLOOKUP(A9,'【3-2】营销中心填-房间模型价 '!B:D,3,0) -> 开间 | D9: 1 | E9: 0 | G9: 0 | H9: =IF(C9="开间",IF(D9+E9*2-G9<=0,"1",IF(D9+E9*2-G9<=1,"2",IF(D9+E9*2-G9<=2,"3",IF(D9+E9*2-G9<=3,"4","5")))),IF(D9+E9*2-G9<1.1,"1",IF(D9+E9*2-G9<=2,"2",IF(D9+E9*2-G9<=3,"3",IF(D9+E9*2-G9<=4,"4","5"))))) -> 2 | I9: 无
A10: ='【3-2】营销中心填-房间模型价 '!B9 -> 108 | B10: ='【3-2】营销中心填-房间模型价 '!C9 -> 6-6E | C10: =VLOOKUP(A10,'【3-2】营销中心填-房间模型价 '!B:D,3,0) -> 开间 | D10: 2 | E10: 0 | G10: 1 | H10: =IF(C10="开间",IF(D10+E10*2-G10<=0,"1",IF(D10+E10*2-G10<=1,"2",IF(D10+E10*2-G10<=2,"3",IF(D10+E10*2-G10<=3,"4","5")))),IF(D10+E10*2-G10<1.1,"1",IF(D10+E10*2-G10<=2,"2",IF(D10+E10*2-G10<=3,"3",IF(D10+E10*2-G10<=4,"4","5"))))) -> 2 | I10: 无
A11: ='【3-2】营销中心填-房间模型价 '!B10 -> 109 | B11: ='【3-2】营销中心填-房间模型价 '!C10 -> 6-6D | C11: =VLOOKUP(A11,'【3-2】营销中心填-房间模型价 '!B:D,3,0) -> 开间 | D11: 0 | E11: 0 | G11: 0 | H11: =IF(C11="开间",IF(D11+E11*2-G11<=0,"1",IF(D11+E11*2-G11<=1,"2",IF(D11+E11*2-G11<=2,"3",IF(D11+E11*2-G11<=3,"4","5")))),IF(D11+E11*2-G11<1.1,"1",IF(D11+E11*2-G11<=2,"2",IF(D11+E11*2-G11<=3,"3",IF(D11+E11*2-G11<=4,"4","5"))))) -> 1 | I11: 无
A12: ='【3-2】营销中心填-房间模型价 '!B11 -> 201 | B12: ='【3-2】营销中心填-房间模型价 '!C11 -> 6-6F | C12: =VLOOKUP(A12,'【3-2】营销中心填-房间模型价 '!B:D,3,0) -> 一居室 | D12: 3 | E12: 0 | G12: 2 | H12: =IF(C12="开间",IF(D12+E12*2-G12<=0,"1",IF(D12+E12*2-G12<=1,"2",IF(D12+E12*2-G12<=2,"3",IF(D12+E12*2-G12<=3,"4","5")))),IF(D12+E12*2-G12<1.1,"1",IF(D12+E12*2-G12<=2,"2",IF(D12+E12*2-G12<=3,"3",IF(D12+E12*2-G12<=4,"4","5"))))) -> 1 | I12: 无
A13: ='【3-2】营销中心填-房间模型价 '!B12 -> 202 | B13: ='【3-2】营销中心填-房间模型价 '!C12 -> 6-6G | C13: =VLOOKUP(A13,'【3-2】营销中心填-房间模型价 '!B:D,3,0) -> 一居室 | D13: 3 | E13: 0 | G13: 3 | H13: =IF(C13="开间",IF(D13+E13*2-G13<=0,"1",IF(D13+E13*2-G13<=1,"2",IF(D13+E13*2-G13<=2,"3",IF(D13+E13*2-G13<=3,"4","5")))),IF(D13+E13*2-G13<1.1,"1",IF(D13+E13*2-G13<=2,"2",IF(D13+E13*2-G13<=3,"3",IF(D13+E13*2-G13<=4,"4","5"))))) -> 1 | I13: 无
A14: ='【3-2】营销中心填-房间模型价 '!B13 -> 203 | B14: ='【3-2】营销中心填-房间模型价 '!C13 -> 6-6H | C14: =VLOOKUP(A14,'【3-2】营销中心填-房间模型价 '!B:D,3,0) -> 开间 | D14: 1 | E14: 0 | G14: 1 | H14: =IF(C14="开间",IF(D14+E14*2-G14<=0,"1",IF(D14+E14*2-G14<=1,"2",IF(D14+E14*2-G14<=2,"3",IF(D14+E14*2-G14<=3,"4","5")))),IF(D14+E14*2-G14<1.1,"1",IF(D14+E14*2-G14<=2,"2",IF(D14+E14*2-G14<=3,"3",IF(D14+E14*2-G14<=4,"4","5"))))) -> 1 | I14: 无
A15: ='【3-2】营销中心填-房间模型价 '!B14 -> 204 | B15: ='【3-2】营销中心填-房间模型价 '!C14 -> 6-6I | C15: =VLOOKUP(A15,'【3-2】营销中心填-房间模型价 '!B:D,3,0) -> 一居室 | D15: 3 | E15: 0 | G15: 3 | H15: =IF(C15="开间",IF(D15+E15*2-G15<=0,"1",IF(D15+E15*2-G15<=1,"2",IF(D15+E15*2-G15<=2,"3",IF(D15+E15*2-G15<=3,"4","5")))),IF(D15+E15*2-G15<1.1,"1",IF(D15+E15*2-G15<=2,"2",IF(D15+E15*2-G15<=3,"3",IF(D15+E15*2-G15<=4,"4","5"))))) -> 1 | I15: 无
A16: ='【3-2】营销中心填-房间模型价 '!B15 -> 205 | B16: ='【3-2】营销中心填-房间模型价 '!C15 -> 6-6J | C16: =VLOOKUP(A16,'【3-2】营销中心填-房间模型价 '!B:D,3,0) -> 开间 | D16: 1 | E16: 0 | G16: 1 | H16: =IF(C16="开间",IF(D16+E16*2-G16<=0,"1",IF(D16+E16*2-G16<=1,"2",IF(D16+E16*2-G16<=2,"3",IF(D16+E16*2-G16<=3,"4","5")))),IF(D16+E16*2-G16<1.1,"1",IF(D16+E16*2-G16<=2,"2",IF(D16+E16*2-G16<=3,"3",IF(D16+E16*2-G16<=4,"4","5"))))) -> 1 | I16: 无 | L16: 以下规格，窗户数按0.5算 | R16: 以下规格，窗户数按1算 | AB16: 以下规格，按窗户数2计算
A17: ='【3-2】营销中心填-房间模型价 '!B16 -> 206 | B17: ='【3-2】营销中心填-房间模型价 '!C16 -> 6-6K | C17: =VLOOKUP(A17,'【3-2】营销中心填-房间模型价 '!B:D,3,0) -> 开间 | D17: 1 | E17: 0 | G17: 1 | H17: =IF(C17="开间",IF(D17+E17*2-G17<=0,"1",IF(D17+E17*2-G17<=1,"2",IF(D17+E17*2-G17<=2,"3",IF(D17+E17*2-G17<=3,"4","5")))),IF(D17+E17*2-G17<1.1,"1",IF(D17+E17*2-G17<=2,"2",IF(D17+E17*2-G17<=3,"3",IF(D17+E17*2-G17<=4,"4","5"))))) -> 1 | I17: 无
A18: ='【3-2】营销中心填-房间模型价 '!B17 -> 207 | B18: ='【3-2】营销中心填-房间模型价 '!C17 -> 6-6L | C18: =VLOOKUP(A18,'【3-2】营销中心填-房间模型价 '!B:D,3,0) -> 开间 | D18: 2 | E18: 0 | G18: 1 | H18: =IF(C18="开间",IF(D18+E18*2-G18<=0,"1",IF(D18+E18*2-G18<=1,"2",IF(D18+E18*2-G18<=2,"3",IF(D18+E18*2-G18<=3,"4","5")))),IF(D18+E18*2-G18<1.1,"1",IF(D18+E18*2-G18<=2,"2",IF(D18+E18*2-G18<=3,"3",IF(D18+E18*2-G18<=4,"4","5"))))) -> 2 | I18: 无
A19: ='【3-2】营销中心填-房间模型价 '!B18 -> 208 | B19: ='【3-2】营销中心填-房间模型价 '!C18 -> 6-6M | C19: =VLOOKUP(A19,'【3-2】营销中心填-房间模型价 '!B:D,3,0) -> 一居室 | D19: 3.5 | E19: 0 | G19: 0 | H19: =IF(C19="开间",IF(D19+E19*2-G19<=0,"1",IF(D19+E19*2-G19<=1,"2",IF(D19+E19*2-G19<=2,"3",IF(D19+E19*2-G19<=3,"4","5")))),IF(D19+E19*2-G19<1.1,"1",IF(D19+E19*2-G19<=2,"2",IF(D19+E19*2-G19<=3,"3",IF(D19+E19*2-G19<=4,"4","5"))))) -> 4 | I19: 无
A20: ='【3-2】营销中心填-房间模型价 '!B19 -> 301 | B20: ='【3-2】营销中心填-房间模型价 '!C19 -> 6-6F | C20: =VLOOKUP(A20,'【3-2】营销中心填-房间模型价 '!B:D,3,0) -> 一居室 | D20: 3 | E20: 0 | G20: 2 | H20: =IF(C20="开间",IF(D20+E20*2-G20<=0,"1",IF(D20+E20*2-G20<=1,"2",IF(D20+E20*2-G20<=2,"3",IF(D20+E20*2-G20<=3,"4","5")))),IF(D20+E20*2-G20<1.1,"1",IF(D20+E20*2-G20<=2,"2",IF(D20+E20*2-G20<=3,"3",IF(D20+E20*2-G20<=4,"4","5"))))) -> 1 | I20: 无
A21: ='【3-2】营销中心填-房间模型价 '!B20 -> 302 | B21: ='【3-2】营销中心填-房间模型价 '!C20 -> 6-6G | C21: =VLOOKUP(A21,'【3-2】营销中心填-房间模型价 '!B:D,3,0) -> 一居室 | D21: 3 | E21: 0 | G21: 3 | H21: =IF(C21="开间",IF(D21+E21*2-G21<=0,"1",IF(D21+E21*2-G21<=1,"2",IF(D21+E21*2-G21<=2,"3",IF(D21+E21*2-G21<=3,"4","5")))),IF(D21+E21*2-G21<1.1,"1",IF(D21+E21*2-G21<=2,"2",IF(D21+E21*2-G21<=3,"3",IF(D21+E21*2-G21<=4,"4","5"))))) -> 1 | I21: 无
A22: ='【3-2】营销中心填-房间模型价 '!B21 -> 303 | B22: ='【3-2】营销中心填-房间模型价 '!C21 -> 6-6H | C22: =VLOOKUP(A22,'【3-2】营销中心填-房间模型价 '!B:D,3,0) -> 开间 | D22: 1 | E22: 0 | G22: 1 | H22: =IF(C22="开间",IF(D22+E22*2-G22<=0,"1",IF(D22+E22*2-G22<=1,"2",IF(D22+E22*2-G22<=2,"3",IF(D22+E22*2-G22<=3,"4","5")))),IF(D22+E22*2-G22<1.1,"1",IF(D22+E22*2-G22<=2,"2",IF(D22+E22*2-G22<=3,"3",IF(D22+E22*2-G22<=4,"4","5"))))) -> 1 | I22: 无
A23: ='【3-2】营销中心填-房间模型价 '!B22 -> 304 | B23: ='【3-2】营销中心填-房间模型价 '!C22 -> 6-6I | C23: =VLOOKUP(A23,'【3-2】营销中心填-房间模型价 '!B:D,3,0) -> 一居室 | D23: 3 | E23: 0 | G23: 3 | H23: =IF(C23="开间",IF(D23+E23*2-G23<=0,"1",IF(D23+E23*2-G23<=1,"2",IF(D23+E23*2-G23<=2,"3",IF(D23+E23*2-G23<=3,"4","5")))),IF(D23+E23*2-G23<1.1,"1",IF(D23+E23*2-G23<=2,"2",IF(D23+E23*2-G23<=3,"3",IF(D23+E23*2-G23<=4,"4","5"))))) -> 1 | I23: 无
A24: ='【3-2】营销中心填-房间模型价 '!B23 -> 305 | B24: ='【3-2】营销中心填-房间模型价 '!C23 -> 6-6J | C24: =VLOOKUP(A24,'【3-2】营销中心填-房间模型价 '!B:D,3,0) -> 开间 | D24: 1 | E24: 0 | G24: 1 | H24: =IF(C24="开间",IF(D24+E24*2-G24<=0,"1",IF(D24+E24*2-G24<=1,"2",IF(D24+E24*2-G24<=2,"3",IF(D24+E24*2-G24<=3,"4","5")))),IF(D24+E24*2-G24<1.1,"1",IF(D24+E24*2-G24<=2,"2",IF(D24+E24*2-G24<=3,"3",IF(D24+E24*2-G24<=4,"4","5"))))) -> 1 | I24: 无
A25: ='【3-2】营销中心填-房间模型价 '!B24 -> 306 | B25: ='【3-2】营销中心填-房间模型价 '!C24 -> 6-6K | C25: =VLOOKUP(A25,'【3-2】营销中心填-房间模型价 '!B:D,3,0) -> 开间 | D25: 1 | E25: 0 | G25: 1 | H25: =IF(C25="开间",IF(D25+E25*2-G25<=0,"1",IF(D25+E25*2-G25<=1,"2",IF(D25+E25*2-G25<=2,"3",IF(D25+E25*2-G25<=3,"4","5")))),IF(D25+E25*2-G25<1.1,"1",IF(D25+E25*2-G25<=2,"2",IF(D25+E25*2-G25<=3,"3",IF(D25+E25*2-G25<=4,"4","5"))))) -> 1 | I25: 无
A26: ='【3-2】营销中心填-房间模型价 '!B25 -> 307 | B26: ='【3-2】营销中心填-房间模型价 '!C25 -> 6-6L | C26: =VLOOKUP(A26,'【3-2】营销中心填-房间模型价 '!B:D,3,0) -> 开间 | D26: 2 | E26: 0 | G26: 1 | H26: =IF(C26="开间",IF(D26+E26*2-G26<=0,"1",IF(D26+E26*2-G26<=1,"2",IF(D26+E26*2-G26<=2,"3",IF(D26+E26*2-G26<=3,"4","5")))),IF(D26+E26*2-G26<1.1,"1",IF(D26+E26*2-G26<=2,"2",IF(D26+E26*2-G26<=3,"3",IF(D26+E26*2-G26<=4,"4","5"))))) -> 2 | I26: 无
A27: ='【3-2】营销中心填-房间模型价 '!B26 -> 308 | B27: ='【3-2】营销中心填-房间模型价 '!C26 -> 6-6M | C27: =VLOOKUP(A27,'【3-2】营销中心填-房间模型价 '!B:D,3,0) -> 一居室 | D27: 3.5 | E27: 0 | G27: 0 | H27: =IF(C27="开间",IF(D27+E27*2-G27<=0,"1",IF(D27+E27*2-G27<=1,"2",IF(D27+E27*2-G27<=2,"3",IF(D27+E27*2-G27<=3,"4","5")))),IF(D27+E27*2-G27<1.1,"1",IF(D27+E27*2-G27<=2,"2",IF(D27+E27*2-G27<=3,"3",IF(D27+E27*2-G27<=4,"4","5"))))) -> 4 | I27: 无
A28: ='【3-2】营销中心填-房间模型价 '!B27 -> 401 | B28: ='【3-2】营销中心填-房间模型价 '!C27 -> 6-6F | C28: =VLOOKUP(A28,'【3-2】营销中心填-房间模型价 '!B:D,3,0) -> 一居室 | D28: 3 | E28: 0 | G28: 2 | H28: =IF(C28="开间",IF(D28+E28*2-G28<=0,"1",IF(D28+E28*2-G28<=1,"2",IF(D28+E28*2-G28<=2,"3",IF(D28+E28*2-G28<=3,"4","5")))),IF(D28+E28*2-G28<1.1,"1",IF(D28+E28*2-G28<=2,"2",IF(D28+E28*2-G28<=3,"3",IF(D28+E28*2-G28<=4,"4","5"))))) -> 1 | I28: 无
... A59: ='【3-2】营销中心填-房间模型价 '!B58 -> 708 | B59: ='【3-2】营销中心填-房间模型价 '!C58 -> 6-6M | C59: =VLOOKUP(A59,'【3-2】营销中心填-房间模型价 '!B:D,3,0) -> 一居室 | D59: 3.5 | E59: 0 | G59: 0 | H59: =IF(C59="开间",IF(D59+E59*2-G59<=0,"1",IF(D59+E59*2-G59<=1,"2",IF(D59+E59*2-G59<=2,"3",IF(D59+E59*2-G59<=3,"4","5")))),IF(D59+E59*2-G59<1.1,"1",IF(D59+E59*2-G59<=2,"2",IF(D59+E59*2-G59<=3,"3",IF(D59+E59*2-G59<=4,"4","5"))))) -> 4 | I59: 无
A60: ='【3-2】营销中心填-房间模型价 '!#REF! -> #REF! | B60: ='【3-2】营销中心填-房间模型价 '!#REF! -> #REF! | C60: =VLOOKUP(A60,'【3-2】营销中心填-房间模型价 '!B:D,3,0) -> #REF! | H60: =IF(C60="开间",IF(D60+E60*2-G60<=0,"1",IF(D60+E60*2-G60<=1,"2",IF(D60+E60*2-G60<=2,"3",IF(D60+E60*2-G60<=3,"4","5")))),IF(D60+E60*2-G60<1.1,"1",IF(D60+E60*2-G60<=2,"2",IF(D60+E60*2-G60<=3,"3",IF(D60+E60*2-G60<=4,"4","5"))))) -> #REF!
A61: ='【3-2】营销中心填-房间模型价 '!#REF! -> #REF! | B61: ='【3-2】营销中心填-房间模型价 '!#REF! -> #REF! | C61: =VLOOKUP(A61,'【3-2】营销中心填-房间模型价 '!B:D,3,0) -> #REF! | H61: =IF(C61="开间",IF(D61+E61*2-G61<=0,"1",IF(D61+E61*2-G61<=1,"2",IF(D61+E61*2-G61<=2,"3",IF(D61+E61*2-G61<=3,"4","5")))),IF(D61+E61*2-G61<1.1,"1",IF(D61+E61*2-G61<=2,"2",IF(D61+E61*2-G61<=3,"3",IF(D61+E61*2-G61<=4,"4","5"))))) -> #REF!
A62: ='【3-2】营销中心填-房间模型价 '!#REF! -> #REF! | B62: ='【3-2】营销中心填-房间模型价 '!#REF! -> #REF! | C62: =VLOOKUP(A62,'【3-2】营销中心填-房间模型价 '!B:D,3,0) -> #REF! | H62: =IF(C62="开间",IF(D62+E62*2-G62<=0,"1",IF(D62+E62*2-G62<=1,"2",IF(D62+E62*2-G62<=2,"3",IF(D62+E62*2-G62<=3,"4","5")))),IF(D62+E62*2-G62<1.1,"1",IF(D62+E62*2-G62<=2,"2",IF(D62+E62*2-G62<=3,"3",IF(D62+E62*2-G62<=4,"4","5"))))) -> #REF!
A63: ='【3-2】营销中心填-房间模型价 '!#REF! -> #REF! | B63: ='【3-2】营销中心填-房间模型价 '!#REF! -> #REF! | C63: =VLOOKUP(A63,'【3-2】营销中心填-房间模型价 '!B:D,3,0) -> #REF! | H63: =IF(C63="开间",IF(D63+E63*2-G63<=0,"1",IF(D63+E63*2-G63<=1,"2",IF(D63+E63*2-G63<=2,"3",IF(D63+E63*2-G63<=3,"4","5")))),IF(D63+E63*2-G63<1.1,"1",IF(D63+E63*2-G63<=2,"2",IF(D63+E63*2-G63<=3,"3",IF(D63+E63*2-G63<=4,"4","5"))))) -> #REF!
A64: ='【3-2】营销中心填-房间模型价 '!#REF! -> #REF! | B64: ='【3-2】营销中心填-房间模型价 '!#REF! -> #REF! | C64: =VLOOKUP(A64,'【3-2】营销中心填-房间模型价 '!B:D,3,0) -> #REF! | H64: =IF(C64="开间",IF(D64+E64*2-G64<=0,"1",IF(D64+E64*2-G64<=1,"2",IF(D64+E64*2-G64<=2,"3",IF(D64+E64*2-G64<=3,"4","5")))),IF(D64+E64*2-G64<1.1,"1",IF(D64+E64*2-G64<=2,"2",IF(D64+E64*2-G64<=3,"3",IF(D64+E64*2-G64<=4,"4","5"))))) -> #REF!
A65: ='【3-2】营销中心填-房间模型价 '!#REF! -> #REF! | B65: ='【3-2】营销中心填-房间模型价 '!#REF! -> #REF! | C65: =VLOOKUP(A65,'【3-2】营销中心填-房间模型价 '!B:D,3,0) -> #REF! | H65: =IF(C65="开间",IF(D65+E65*2-G65<=0,"1",IF(D65+E65*2-G65<=1,"2",IF(D65+E65*2-G65<=2,"3",IF(D65+E65*2-G65<=3,"4","5")))),IF(D65+E65*2-G65<1.1,"1",IF(D65+E65*2-G65<=2,"2",IF(D65+E65*2-G65<=3,"3",IF(D65+E65*2-G65<=4,"4","5"))))) -> #REF!
A66: ='【3-2】营销中心填-房间模型价 '!#REF! -> #REF! | B66: ='【3-2】营销中心填-房间模型价 '!#REF! -> #REF! | C66: =VLOOKUP(A66,'【3-2】营销中心填-房间模型价 '!B:D,3,0) -> #REF! | H66: =IF(C66="开间",IF(D66+E66*2-G66<=0,"1",IF(D66+E66*2-G66<=1,"2",IF(D66+E66*2-G66<=2,"3",IF(D66+E66*2-G66<=3,"4","5")))),IF(D66+E66*2-G66<1.1,"1",IF(D66+E66*2-G66<=2,"2",IF(D66+E66*2-G66<=3,"3",IF(D66+E66*2-G66<=4,"4","5"))))) -> #REF!
A67: ='【3-2】营销中心填-房间模型价 '!#REF! -> #REF! | B67: ='【3-2】营销中心填-房间模型价 '!#REF! -> #REF! | C67: =VLOOKUP(A67,'【3-2】营销中心填-房间模型价 '!B:D,3,0) -> #REF! | H67: =IF(C67="开间",IF(D67+E67*2-G67<=0,"1",IF(D67+E67*2-G67<=1,"2",IF(D67+E67*2-G67<=2,"3",IF(D67+E67*2-G67<=3,"4","5")))),IF(D67+E67*2-G67<1.1,"1",IF(D67+E67*2-G67<=2,"2",IF(D67+E67*2-G67<=3,"3",IF(D67+E67*2-G67<=4,"4","5"))))) -> #REF!
A68: ='【3-2】营销中心填-房间模型价 '!#REF! -> #REF! | B68: ='【3-2】营销中心填-房间模型价 '!#REF! -> #REF! | C68: =VLOOKUP(A68,'【3-2】营销中心填-房间模型价 '!B:D,3,0) -> #REF! | H68: =IF(C68="开间",IF(D68+E68*2-G68<=0,"1",IF(D68+E68*2-G68<=1,"2",IF(D68+E68*2-G68<=2,"3",IF(D68+E68*2-G68<=3,"4","5")))),IF(D68+E68*2-G68<1.1,"1",IF(D68+E68*2-G68<=2,"2",IF(D68+E68*2-G68<=3,"3",IF(D68+E68*2-G68<=4,"4","5"))))) -> #REF!
A69: ='【3-2】营销中心填-房间模型价 '!#REF! -> #REF! | B69: ='【3-2】营销中心填-房间模型价 '!#REF! -> #REF! | C69: =VLOOKUP(A69,'【3-2】营销中心填-房间模型价 '!B:D,3,0) -> #REF! | H69: =IF(C69="开间",IF(D69+E69*2-G69<=0,"1",IF(D69+E69*2-G69<=1,"2",IF(D69+E69*2-G69<=2,"3",IF(D69+E69*2-G69<=3,"4","5")))),IF(D69+E69*2-G69<1.1,"1",IF(D69+E69*2-G69<=2,"2",IF(D69+E69*2-G69<=3,"3",IF(D69+E69*2-G69<=4,"4","5"))))) -> #REF!
A70: ='【3-2】营销中心填-房间模型价 '!#REF! -> #REF! | B70: ='【3-2】营销中心填-房间模型价 '!#REF! -> #REF! | C70: =VLOOKUP(A70,'【3-2】营销中心填-房间模型价 '!B:D,3,0) -> #REF! | H70: =IF(C70="开间",IF(D70+E70*2-G70<=0,"1",IF(D70+E70*2-G70<=1,"2",IF(D70+E70*2-G70<=2,"3",IF(D70+E70*2-G70<=3,"4","5")))),IF(D70+E70*2-G70<1.1,"1",IF(D70+E70*2-G70<=2,"2",IF(D70+E70*2-G70<=3,"3",IF(D70+E70*2-G70<=4,"4","5"))))) -> #REF!
...

Sheet 【3-2】营销中心填-房间模型价 
A1: 楼栋 | B1: 房间号 | C1: 户型 | D1: 基准格局 | E1: 基准格局定价 | F1: 套内空间 | G1: 调价倍数1 | H1: 阳台 | I1: 调价倍数3 | J1: 楼梯房楼层 | K1: 调价倍数4 | L1: 电梯房楼层 | M1: 调价倍数5 | N1: =定价因子!C38 -> 功能配置（开间） | O1: 调价倍数6 | P1: =定价因子!$C$51 -> 功能配置（一居） | Q1: 调价倍数8 | R1: 采光 | S1: 调价倍数7 | T1: 房间模型价 | U1: 实际定价 | V1: 折后价 | W1: 折后全包 | X1: 差距
A2: ='【1】基本信息&审核标准'!$E$2 -> 6-6栋 | B2: 101 | C2: 6-6A | D2: 开间 | E2: =VLOOKUP(D2,'【2】运营中心填-楼栋基准格局定价'!B:H,7,0) -> 1449.8 | F2: 适中 | G2: =VLOOKUP($F$1&F2,定价因子!E:F,2,0) -> 1 | H2: 无 | I2: =VLOOKUP($H$1&H2,定价因子!E:F,2,0) -> 1 | J2: 1F | K2: =VLOOKUP(J2,定价因子!D:F,3,0) -> 0.91 | L2: 无 | M2: =VLOOKUP($L$1&L2,定价因子!E:F,2,0) -> 1 | N2: 适中 | O2: =VLOOKUP($N$1&N2,定价因子!E:F,2,0) -> 1 | P2: 适中 | Q2: =VLOOKUP($P$1&P2,定价因子!$E:$F,2,0) -> 1 | R2: 1 | S2: =VLOOKUP($R$1&R2,定价因子!$E:$F,2,0) -> 0.91 | T2: =E2*PRODUCT(Q2,S2,O2,M2,K2,I2,G2) -> 1200.5794 | U2: 950 | V2: =U2*0.85*0.9 -> 726.75 | W2: =V2+U2*0.09+99 -> 911.25 | X2: =U2/T2-1 -> -0.20871538
A3: ='【1】基本信息&审核标准'!$E$2 -> 6-6栋 | B3: 102 | C3: 6-6A | D3: 开间 | E3: =VLOOKUP(D3,'【2】运营中心填-楼栋基准格局定价'!B:H,7,0) -> 1449.8 | F3: 适中 | G3: =VLOOKUP($F$1&F3,定价因子!E:F,2,0) -> 1 | H3: 无 | I3: =VLOOKUP($H$1&H3,定价因子!E:F,2,0) -> 1 | J3: 1F | K3: =VLOOKUP(J3,定价因子!D:F,3,0) -> 0.91 | L3: 无 | M3: =VLOOKUP($L$1&L3,定价因子!E:F,2,0) -> 1 | N3: 适中 | O3: =VLOOKUP($N$1&N3,定价因子!E:F,2,0) -> 1 | P3: 适中 | Q3: =VLOOKUP($P$1&P3,定价因子!$E:$F,2,0) -> 1 | R3: 1 | S3: =VLOOKUP($R$1&R3,定价因子!$E:$F,2,0) -> 0.91 | T3: =E3*PRODUCT(Q3,S3,O3,M3,K3,I3,G3) -> 1200.5794 | U3: 950 | V3: =U3*0.85*0.9 -> 726.75 | W3: =V3+U3*0.09+99 -> 911.25 | X3: =U3/T3-1 -> -0.20871538
A4: ='【1】基本信息&审核标准'!$E$2 -> 6-6栋 | B4: 103 | C4: 6-6B | D4: 开间 | E4: =VLOOKUP(D4,'【2】运营中心填-楼栋基准格局定价'!B:H,7,0) -> 1449.8 | F4: 较宽敞 | G4: =VLOOKUP($F$1&F4,定价因子!E:F,2,0) -> 1.06 | H4: 无 | I4: =VLOOKUP($H$1&H4,定价因子!E:F,2,0) -> 1 | J4: 1F | K4: =VLOOKUP(J4,定价因子!D:F,3,0) -> 0.91 | L4: 无 | M4: =VLOOKUP($L$1&L4,定价因子!E:F,2,0) -> 1 | N4: 充足（油烟机/沙发） | O4: =VLOOKUP($N$1&N4,定价因子!E:F,2,0) -> 1.04 | P4: 适中 | Q4: =VLOOKUP($P$1&P4,定价因子!$E:$F,2,0) -> 1 | R4: 1 | S4: =VLOOKUP($R$1&R4,定价因子!$E:$F,2,0) -> 0.91 | T4: =E4*PRODUCT(Q4,S4,O4,M4,K4,I4,G4) -> 1323.5187 | U4: 1200 | V4: =U4*0.85*0.9 -> 918 | W4: =V4+U4*0.09+99 -> 1125 | X4: =U4/T4-1 -> -0.093326001
A5: ='【1】基本信息&审核标准'!$E$2 -> 6-6栋 | B5: 104 | C5: 6-6C | D5: 开间 | E5: =VLOOKUP(D5,'【2】运营中心填-楼栋基准格局定价'!B:H,7,0) -> 1449.8 | F5: 较狭小 | G5: =VLOOKUP($F$1&F5,定价因子!E:F,2,0) -> 0.95 | H5: 无 | I5: =VLOOKUP($H$1&H5,定价因子!E:F,2,0) -> 1 | J5: 1F | K5: =VLOOKUP(J5,定价因子!D:F,3,0) -> 0.91 | L5: 无 | M5: =VLOOKUP($L$1&L5,定价因子!E:F,2,0) -> 1 | N5: 适中 | O5: =VLOOKUP($N$1&N5,定价因子!E:F,2,0) -> 1 | P5: 适中 | Q5: =VLOOKUP($P$1&P5,定价因子!$E:$F,2,0) -> 1 | R5: 1 | S5: =VLOOKUP($R$1&R5,定价因子!$E:$F,2,0) -> 0.91 | T5: =E5*PRODUCT(Q5,S5,O5,M5,K5,I5,G5) -> 1140.5504 | U5: 950 | V5: =U5*0.85*0.9 -> 726.75 | W5: =V5+U5*0.09+99 -> 911.25 | X5: =U5/T5-1 -> -0.16706882
A6: ='【1】基本信息&审核标准'!$E$2 -> 6-6栋 | B6: 105 | C6: 6-6D | D6: 开间 | E6: =VLOOKUP(D6,'【2】运营中心填-楼栋基准格局定价'!B:H,7,0) -> 1449.8 | F6: 较狭小 | G6: =VLOOKUP($F$1&F6,定价因子!E:F,2,0) -> 0.95 | H6: 无 | I6: =VLOOKUP($H$1&H6,定价因子!E:F,2,0) -> 1 | J6: 1F | K6: =VLOOKUP(J6,定价因子!D:F,3,0) -> 0.91 | L6: 无 | M6: =VLOOKUP($L$1&L6,定价因子!E:F,2,0) -> 1 | N6: 适中 | O6: =VLOOKUP($N$1&N6,定价因子!E:F,2,0) -> 1 | P6: 适中 | Q6: =VLOOKUP($P$1&P6,定价因子!$E:$F,2,0) -> 1 | R6: 1 | S6: =VLOOKUP($R$1&R6,定价因子!$E:$F,2,0) -> 0.91 | T6: =E6*PRODUCT(Q6,S6,O6,M6,K6,I6,G6) -> 1140.5504 | U6: 1030 | V6: =U6*0.85*0.9 -> 787.95 | W6: =V6+U6*0.09+99 -> 979.65 | X6: =U6/T6-1 -> -0.096927247
A7: ='【1】基本信息&审核标准'!$E$2 -> 6-6栋 | B7: 106 | C7: 6-6D | D7: 开间 | E7: =VLOOKUP(D7,'【2】运营中心填-楼栋基准格局定价'!B:H,7,0) -> 1449.8 | F7: 较狭小 | G7: =VLOOKUP($F$1&F7,定价因子!E:F,2,0) -> 0.95 | H7: 无 | I7: =VLOOKUP($H$1&H7,定价因子!E:F,2,0) -> 1 | J7: 1F | K7: =VLOOKUP(J7,定价因子!D:F,3,0) -> 0.91 | L7: 无 | M7: =VLOOKUP($L$1&L7,定价因子!E:F,2,0) -> 1 | N7: 适中 | O7: =VLOOKUP($N$1&N7,定价因子!E:F,2,0) -> 1 | P7: 适中 | Q7: =VLOOKUP($P$1&P7,定价因子!$E:$F,2,0) -> 1 | R7: 1 | S7: =VLOOKUP($R$1&R7,定价因子!$E:$F,2,0) -> 0.91 | T7: =E7*PRODUCT(Q7,S7,O7,M7,K7,I7,G7) -> 1140.5504 | U7: 1030 | V7: =U7*0.85*0.9 -> 787.95 | W7: =V7+U7*0.09+99 -> 979.65 | X7: =U7/T7-1 -> -0.096927247
A8: ='【1】基本信息&审核标准'!$E$2 -> 6-6栋 | B8: 107 | C8: 6-6C | D8: 开间 | E8: =VLOOKUP(D8,'【2】运营中心填-楼栋基准格局定价'!B:H,7,0) -> 1449.8 | F8: 较狭小 | G8: =VLOOKUP($F$1&F8,定价因子!E:F,2,0) -> 0.95 | H8: 无 | I8: =VLOOKUP($H$1&H8,定价因子!E:F,2,0) -> 1 | J8: 1F | K8: =VLOOKUP(J8,定价因子!D:F,3,0) -> 0.91 | L8: 无 | M8: =VLOOKUP($L$1&L8,定价因子!E:F,2,0) -> 1 | N8: 适中 | O8: =VLOOKUP($N$1&N8,定价因子!E:F,2,0) -> 1 | P8: 适中 | Q8: =VLOOKUP($P$1&P8,定价因子!$E:$F,2,0) -> 1 | R8: 2 | S8: =VLOOKUP($R$1&R8,定价因子!$E:$F,2,0) -> 0.96 | T8: =E8*PRODUCT(Q8,S8,O8,M8,K8,I8,G8) -> 1203.218 | U8: 950 | V8: =U8*0.85*0.9 -> 726.75 | W8: =V8+U8*0.09+99 -> 911.25 | X8: =U8/T8-1 -> -0.21045065
A9: ='【1】基本信息&审核标准'!$E$2 -> 6-6栋 | B9: 108 | C9: 6-6E | D9: 开间 | E9: =VLOOKUP(D9,'【2】运营中心填-楼栋基准格局定价'!B:H,7,0) -> 1449.8 | F9: 较狭小 | G9: =VLOOKUP($F$1&F9,定价因子!E:F,2,0) -> 0.95 | H9: 无 | I9: =VLOOKUP($H$1&H9,定价因子!E:F,2,0) -> 1 | J9: 1F | K9: =VLOOKUP(J9,定价因子!D:F,3,0) -> 0.91 | L9: 无 | M9: =VLOOKUP($L$1&L9,定价因子!E:F,2,0) -> 1 | N9: 适中 | O9: =VLOOKUP($N$1&N9,定价因子!E:F,2,0) -> 1 | P9: 适中 | Q9: =VLOOKUP($P$1&P9,定价因子!$E:$F,2,0) -> 1 | R9: 2 | S9: =VLOOKUP($R$1&R9,定价因子!$E:$F,2,0) -> 0.96 | T9: =E9*PRODUCT(Q9,S9,O9,M9,K9,I9,G9) -> 1203.218 | U9: 950 | V9: =U9*0.85*0.9 -> 726.75 | W9: =V9+U9*0.09+99 -> 911.25 | X9: =U9/T9-1 -> -0.21045065
A10: ='【1】基本信息&审核标准'!$E$2 -> 6-6栋 | B10: 109 | C10: 6-6D | D10: 开间 | E10: =VLOOKUP(D10,'【2】运营中心填-楼栋基准格局定价'!B:H,7,0) -> 1449.8 | F10: 较狭小 | G10: =VLOOKUP($F$1&F10,定价因子!E:F,2,0) -> 0.95 | H10: 无 | I10: =VLOOKUP($H$1&H10,定价因子!E:F,2,0) -> 1 | J10: 1F | K10: =VLOOKUP(J10,定价因子!D:F,3,0) -> 0.91 | L10: 无 | M10: =VLOOKUP($L$1&L10,定价因子!E:F,2,0) -> 1 | N10: 适中 | O10: =VLOOKUP($N$1&N10,定价因子!E:F,2,0) -> 1 | P10: 适中 | Q10: =VLOOKUP($P$1&P10,定价因子!$E:$F,2,0) -> 1 | R10: 1 | S10: =VLOOKUP($R$1&R10,定价因子!$E:$F,2,0) -> 0.91 | T10: =E10*PRODUCT(Q10,S10,O10,M10,K10,I10,G10) -> 1140.5504 | U10: 1030 | V10: =U10*0.85*0.9 -> 787.95 | W10: =V10+U10*0.09+99 -> 979.65 | X10: =U10/T10-1 -> -0.096927247
A11: ='【1】基本信息&审核标准'!$E$2 -> 6-6栋 | B11: 201 | C11: 6-6F | D11: 一居室 | E11: =VLOOKUP(D11,'【2】运营中心填-楼栋基准格局定价'!B:H,7,0) -> 2219.7 | F11: 适中 | G11: =VLOOKUP($F$1&F11,定价因子!E:F,2,0) -> 1 | H11: 无 | I11: =VLOOKUP($H$1&H11,定价因子!E:F,2,0) -> 1 | J11: 2F | K11: =VLOOKUP(J11,定价因子!D:F,3,0) -> 1.02 | L11: 无 | M11: =VLOOKUP($L$1&L11,定价因子!E:F,2,0) -> 1 | N11: 适中 | O11: =VLOOKUP($N$1&N11,定价因子!E:F,2,0) -> 1 | P11: 充配（书桌） | Q11: =VLOOKUP($P$1&P11,定价因子!$E:$F,2,0) -> 1.02 | R11: 1 | S11: =VLOOKUP($R$1&R11,定价因子!$E:$F,2,0) -> 0.91 | T11: =E11*PRODUCT(Q11,S11,O11,M11,K11,I11,G11) -> 2101.5321 | U11: 2129 | V11: =U11*0.85*0.9 -> 1628.685 | W11: =V11+U11*0.09+99 -> 1919.295 | X11: =U11/T11-1 -> 0.01307044
A12: ='【1】基本信息&审核标准'!$E$2 -> 6-6栋 | B12: 202 | C12: 6-6G | D12: 一居室 | E12: =VLOOKUP(D12,'【2】运营中心填-楼栋基准格局定价'!B:H,7,0) -> 2219.7 | F12: 较狭小 | G12: =VLOOKUP($F$1&F12,定价因子!E:F,2,0) -> 0.95 | H12: 无 | I12: =VLOOKUP($H$1&H12,定价因子!E:F,2,0) -> 1 | J12: 2F | K12: =VLOOKUP(J12,定价因子!D:F,3,0) -> 1.02 | L12: 无 | M12: =VLOOKUP($L$1&L12,定价因子!E:F,2,0) -> 1 | N12: 适中 | O12: =VLOOKUP($N$1&N12,定价因子!E:F,2,0) -> 1 | P12: 充配（书桌） | Q12: =VLOOKUP($P$1&P12,定价因子!$E:$F,2,0) -> 1.02 | R12: 1 | S12: =VLOOKUP($R$1&R12,定价因子!$E:$F,2,0) -> 0.91 | T12: =E12*PRODUCT(Q12,S12,O12,M12,K12,I12,G12) -> 1996.4554 | U12: 2059 | V12: =U12*0.85*0.9 -> 1575.135 | W12: =V12+U12*0.09+99 -> 1859.445 | X12: =U12/T12-1 -> 0.031327797
A13: ='【1】基本信息&审核标准'!$E$2 -> 6-6栋 | B13: 203 | C13: 6-6H | D13: 开间 | E13: =VLOOKUP(D13,'【2】运营中心填-楼栋基准格局定价'!B:H,7,0) -> 1449.8 | F13: 适中 | G13: =VLOOKUP($F$1&F13,定价因子!E:F,2,0) -> 1 | H13: 无 | I13: =VLOOKUP($H$1&H13,定价因子!E:F,2,0) -> 1 | J13: 2F | K13: =VLOOKUP(J13,定价因子!D:F,3,0) -> 1.02 | L13: 无 | M13: =VLOOKUP($L$1&L13,定价因子!E:F,2,0) -> 1 | N13: 适中 | O13: =VLOOKUP($N$1&N13,定价因子!E:F,2,0) -> 1 | P13: 适中 | Q13: =VLOOKUP($P$1&P13,定价因子!$E:$F,2,0) -> 1 | R13: 1 | S13: =VLOOKUP($R$1&R13,定价因子!$E:$F,2,0) -> 0.91 | T13: =E13*PRODUCT(Q13,S13,O13,M13,K13,I13,G13) -> 1345.7044 | U13: 1212 | V13: =U13*0.85*0.9 -> 927.18 | W13: =V13+U13*0.09+99 -> 1135.26 | X13: =U13/T13-1 -> -0.099356414
... A18: ='【1】基本信息&审核标准'!$E$2 -> 6-6栋 | B18: 208 | C18: 6-6M | D18: 一居室 | E18: =VLOOKUP(D18,'【2】运营中心填-楼栋基准格局定价'!B:H,7,0) -> 2219.7 | F18: 较狭小 | G18: =VLOOKUP($F$1&F18,定价因子!E:F,2,0) -> 0.95 | H18: 无 | I18: =VLOOKUP($H$1&H18,定价因子!E:F,2,0) -> 1 | J18: 2F | K18: =VLOOKUP(J18,定价因子!D:F,3,0) -> 1.02 | L18: 无 | M18: =VLOOKUP($L$1&L18,定价因子!E:F,2,0) -> 1 | N18: 适中 | O18: =VLOOKUP($N$1&N18,定价因子!E:F,2,0) -> 1 | P18: 充配（油烟机） | Q18: =VLOOKUP($P$1&P18,定价因子!$E:$F,2,0) -> 1.04 | R18: 4 | S18: =VLOOKUP($R$1&R18,定价因子!$E:$F,2,0) -> 1.03 | T18: =E18*PRODUCT(Q18,S18,O18,M18,K18,I18,G18) -> 2304.0326 | U18: 2279 | V18: =U18*0.85*0.9 -> 1743.435 | W18: =V18+U18*0.09+99 -> 2047.545 | X18: =U18/T18-1 -> -0.010864698
A19: ='【1】基本信息&审核标准'!$E$2 -> 6-6栋 | B19: 301 | C19: 6-6F | D19: 一居室 | E19: =VLOOKUP(D19,'【2】运营中心填-楼栋基准格局定价'!B:H,7,0) -> 2219.7 | F19: 适中 | G19: =VLOOKUP($F$1&F19,定价因子!E:F,2,0) -> 1 | H19: 无 | I19: =VLOOKUP($H$1&H19,定价因子!E:F,2,0) -> 1 | J19: 3F | K19: =VLOOKUP(J19,定价因子!D:F,3,0) -> 1.01 | L19: 无 | M19: =VLOOKUP($L$1&L19,定价因子!E:F,2,0) -> 1 | N19: 适中 | O19: =VLOOKUP($N$1&N19,定价因子!E:F,2,0) -> 1 | P19: 充配（书桌） | Q19: =VLOOKUP($P$1&P19,定价因子!$E:$F,2,0) -> 1.02 | R19: 1 | S19: =VLOOKUP($R$1&R19,定价因子!$E:$F,2,0) -> 0.91 | T19: =E19*PRODUCT(Q19,S19,O19,M19,K19,I19,G19) -> 2080.9288 | U19: =U11 -> 2129 | V19: =U19*0.85*0.9 -> 1628.685 | W19: =V19+U19*0.09+99 -> 1919.295 | X19: =U19/T19-1 -> 0.023100841
A20: ='【1】基本信息&审核标准'!$E$2 -> 6-6栋 | B20: 302 | C20: 6-6G | D20: 一居室 | E20: =VLOOKUP(D20,'【2】运营中心填-楼栋基准格局定价'!B:H,7,0) -> 2219.7 | F20: 较狭小 | G20: =VLOOKUP($F$1&F20,定价因子!E:F,2,0) -> 0.95 | H20: 无 | I20: =VLOOKUP($H$1&H20,定价因子!E:F,2,0) -> 1 | J20: 3F | K20: =VLOOKUP(J20,定价因子!D:F,3,0) -> 1.01 | L20: 无 | M20: =VLOOKUP($L$1&L20,定价因子!E:F,2,0) -> 1 | N20: 适中 | O20: =VLOOKUP($N$1&N20,定价因子!E:F,2,0) -> 1 | P20: 充配（书桌） | Q20: =VLOOKUP($P$1&P20,定价因子!$E:$F,2,0) -> 1.02 | R20: 1 | S20: =VLOOKUP($R$1&R20,定价因子!$E:$F,2,0) -> 0.91 | T20: =E20*PRODUCT(Q20,S20,O20,M20,K20,I20,G20) -> 1976.8824 | U20: 2059 | V20: =U20*0.85*0.9 -> 1575.135 | W20: =V20+U20*0.09+99 -> 1859.445 | X20: =U20/T20-1 -> 0.041538964
A21: ='【1】基本信息&审核标准'!$E$2 -> 6-6栋 | B21: 303 | C21: 6-6H | D21: 开间 | E21: =VLOOKUP(D21,'【2】运营中心填-楼栋基准格局定价'!B:H,7,0) -> 1449.8 | F21: 适中 | G21: =VLOOKUP($F$1&F21,定价因子!E:F,2,0) -> 1 | H21: 无 | I21: =VLOOKUP($H$1&H21,定价因子!E:F,2,0) -> 1 | J21: 3F | K21: =VLOOKUP(J21,定价因子!D:F,3,0) -> 1.01 | L21: 无 | M21: =VLOOKUP($L$1&L21,定价因子!E:F,2,0) -> 1 | N21: 适中 | O21: =VLOOKUP($N$1&N21,定价因子!E:F,2,0) -> 1 | P21: 适中 | Q21: =VLOOKUP($P$1&P21,定价因子!$E:$F,2,0) -> 1 | R21: 1 | S21: =VLOOKUP($R$1&R21,定价因子!$E:$F,2,0) -> 0.91 | T21: =E21*PRODUCT(Q21,S21,O21,M21,K21,I21,G21) -> 1332.5112 | U21: 1200 | V21: =U21*0.85*0.9 -> 918 | W21: =V21+U21*0.09+99 -> 1125 | X21: =U21/T21-1 -> -0.099444704
A22: ='【1】基本信息&审核标准'!$E$2 -> 6-6栋 | B22: 304 | C22: 6-6I | D22: 一居室 | E22: =VLOOKUP(D22,'【2】运营中心填-楼栋基准格局定价'!B:H,7,0) -> 2219.7 | F22: 较狭小 | G22: =VLOOKUP($F$1&F22,定价因子!E:F,2,0) -> 0.95 | H22: 无 | I22: =VLOOKUP($H$1&H22,定价因子!E:F,2,0) -> 1 | J22: 3F | K22: =VLOOKUP(J22,定价因子!D:F,3,0) -> 1.01 | L22: 无 | M22: =VLOOKUP($L$1&L22,定价因子!E:F,2,0) -> 1 | N22: 适中 | O22: =VLOOKUP($N$1&N22,定价因子!E:F,2,0) -> 1 | P22: 充配（书桌） | Q22: =VLOOKUP($P$1&P22,定价因子!$E:$F,2,0) -> 1.02 | R22: 1 | S22: =VLOOKUP($R$1&R22,定价因子!$E:$F,2,0) -> 0.91 | T22: =E22*PRODUCT(Q22,S22,O22,M22,K22,I22,G22) -> 1976.8824 | U22: 1780 | V22: =U22*0.85*0.9 -> 1361.7 | W22: =V22+U22*0.09+99 -> 1620.9 | X22: =U22/T22-1 -> -0.099592348
A23: ='【1】基本信息&审核标准'!$E$2 -> 6-6栋 | B23: 305 | C23: 6-6J | D23: 开间 | E23: =VLOOKUP(D23,'【2】运营中心填-楼栋基准格局定价'!B:H,7,0) -> 1449.8 | F23: 较狭小 | G23: =VLOOKUP($F$1&F23,定价因子!E:F,2,0) -> 0.95 | H23: 无 | I23: =VLOOKUP($H$1&H23,定价因子!E:F,2,0) -> 1 | J23: 3F | K23: =VLOOKUP(J23,定价因子!D:F,3,0) -> 1.01 | L23: 无 | M23: =VLOOKUP($L$1&L23,定价因子!E:F,2,0) -> 1 | N23: 适中 | O23: =VLOOKUP($N$1&N23,定价因子!E:F,2,0) -> 1 | P23: 适中 | Q23: =VLOOKUP($P$1&P23,定价因子!$E:$F,2,0) -> 1 | R23: 1 | S23: =VLOOKUP($R$1&R23,定价因子!$E:$F,2,0) -> 0.91 | T23: =E23*PRODUCT(Q23,S23,O23,M23,K23,I23,G23) -> 1265.8856 | U23: 1140 | V23: =U23*0.85*0.9 -> 872.1 | W23: =V23+U23*0.09+99 -> 1073.7 | X23: =U23/T23-1 -> -0.099444704
A24: ='【1】基本信息&审核标准'!$E$2 -> 6-6栋 | B24: 306 | C24: 6-6K | D24: 开间 | E24: =VLOOKUP(D24,'【2】运营中心填-楼栋基准格局定价'!B:H,7,0) -> 1449.8 | F24: 较狭小 | G24: =VLOOKUP($F$1&F24,定价因子!E:F,2,0) -> 0.95 | H24: 无 | I24: =VLOOKUP($H$1&H24,定价因子!E:F,2,0) -> 1 | J24: 3F | K24: =VLOOKUP(J24,定价因子!D:F,3,0) -> 1.01 | L24: 无 | M24: =VLOOKUP($L$1&L24,定价因子!E:F,2,0) -> 1 | N24: 适中 | O24: =VLOOKUP($N$1&N24,定价因子!E:F,2,0) -> 1 | P24: 适中 | Q24: =VLOOKUP($P$1&P24,定价因子!$E:$F,2,0) -> 1 | R24: 1 | S24: =VLOOKUP($R$1&R24,定价因子!$E:$F,2,0) -> 0.91 | T24: =E24*PRODUCT(Q24,S24,O24,M24,K24,I24,G24) -> 1265.8856 | U24: 1140 | V24: =U24*0.85*0.9 -> 872.1 | W24: =V24+U24*0.09+99 -> 1073.7 | X24: =U24/T24-1 -> -0.099444704
A25: ='【1】基本信息&审核标准'!$E$2 -> 6-6栋 | B25: 307 | C25: 6-6L | D25: 开间 | E25: =VLOOKUP(D25,'【2】运营中心填-楼栋基准格局定价'!B:H,7,0) -> 1449.8 | F25: 适中 | G25: =VLOOKUP($F$1&F25,定价因子!E:F,2,0) -> 1 | H25: 无 | I25: =VLOOKUP($H$1&H25,定价因子!E:F,2,0) -> 1 | J25: 3F | K25: =VLOOKUP(J25,定价因子!D:F,3,0) -> 1.01 | L25: 无 | M25: =VLOOKUP($L$1&L25,定价因子!E:F,2,0) -> 1 | N25: 充足（单人沙发/餐桌椅） | O25: =VLOOKUP($N$1&N25,定价因子!E:F,2,0) -> 1.03 | P25: 适中 | Q25: =VLOOKUP($P$1&P25,定价因子!$E:$F,2,0) -> 1 | R25: 2 | S25: =VLOOKUP($R$1&R25,定价因子!$E:$F,2,0) -> 0.96 | T25: =E25*PRODUCT(Q25,S25,O25,M25,K25,I25,G25) -> 1447.8979 | U25: =U17 -> 1450 | V25: =U25*0.85*0.9 -> 1109.25 | W25: =V25+U25*0.09+99 -> 1338.75 | X25: =U25/T25-1 -> 0.0014518549
A26: ='【1】基本信息&审核标准'!$E$2 -> 6-6栋 | B26: 308 | C26: 6-6M | D26: 一居室 | E26: =VLOOKUP(D26,'【2】运营中心填-楼栋基准格局定价'!B:H,7,0) -> 2219.7 | F26: 较狭小 | G26: =VLOOKUP($F$1&F26,定价因子!E:F,2,0) -> 0.95 | H26: 无 | I26: =VLOOKUP($H$1&H26,定价因子!E:F,2,0) -> 1 | J26: 3F | K26: =VLOOKUP(J26,定价因子!D:F,3,0) -> 1.01 | L26: 无 | M26: =VLOOKUP($L$1&L26,定价因子!E:F,2,0) -> 1 | N26: 适中 | O26: =VLOOKUP($N$1&N26,定价因子!E:F,2,0) -> 1 | P26: 充配（油烟机） | Q26: =VLOOKUP($P$1&P26,定价因子!$E:$F,2,0) -> 1.04 | R26: 4 | S26: =VLOOKUP($R$1&R26,定价因子!$E:$F,2,0) -> 1.03 | T26: =E26*PRODUCT(Q26,S26,O26,M26,K26,I26,G26) -> 2281.4441 | U26: 2279 | V26: =U26*0.85*0.9 -> 1743.435 | W26: =V26+U26*0.09+99 -> 2047.545 | X26: =U26/T26-1 -> -0.001071279
A27: ='【1】基本信息&审核标准'!$E$2 -> 6-6栋 | B27: 401 | C27: 6-6F | D27: 一居室 | E27: =VLOOKUP(D27,'【2】运营中心填-楼栋基准格局定价'!B:H,7,0) -> 2219.7 | F27: 适中 | G27: =VLOOKUP($F$1&F27,定价因子!E:F,2,0) -> 1 | H27: 无 | I27: =VLOOKUP($H$1&H27,定价因子!E:F,2,0) -> 1 | J27: 4F | K27: =VLOOKUP(J27,定价因子!D:F,3,0) -> 1 | L27: 无 | M27: =VLOOKUP($L$1&L27,定价因子!E:F,2,0) -> 1 | N27: 适中 | O27: =VLOOKUP($N$1&N27,定价因子!E:F,2,0) -> 1 | P27: 充配（书桌） | Q27: =VLOOKUP($P$1&P27,定价因子!$E:$F,2,0) -> 1.02 | R27: 1 | S27: =VLOOKUP($R$1&R27,定价因子!$E:$F,2,0) -> 0.91 | T27: =E27*PRODUCT(Q27,S27,O27,M27,K27,I27,G27) -> 2060.3255 | U27: 2079 | V27: =U27*0.85*0.9 -> 1590.435 | W27: =V27+U27*0.09+99 -> 1876.545 | X27: =U27/T27-1 -> 0.0090638395
A28: ='【1】基本信息&审核标准'!$E$2 -> 6-6栋 | B28: 402 | C28: 6-6G | D28: 一居室 | E28: =VLOOKUP(D28,'【2】运营中心填-楼栋基准格局定价'!B:H,7,0) -> 2219.7 | F28: 较狭小 | G28: =VLOOKUP($F$1&F28,定价因子!E:F,2,0) -> 0.95 | H28: 无 | I28: =VLOOKUP($H$1&H28,定价因子!E:F,2,0) -> 1 | J28: 4F | K28: =VLOOKUP(J28,定价因子!D:F,3,0) -> 1 | L28: 无 | M28: =VLOOKUP($L$1&L28,定价因子!E:F,2,0) -> 1 | N28: 适中 | O28: =VLOOKUP($N$1&N28,定价因子!E:F,2,0) -> 1 | P28: 充配（书桌） | Q28: =VLOOKUP($P$1&P28,定价因子!$E:$F,2,0) -> 1.02 | R28: 1 | S28: =VLOOKUP($R$1&R28,定价因子!$E:$F,2,0) -> 0.91 | T28: =E28*PRODUCT(Q28,S28,O28,M28,K28,I28,G28) -> 1957.3093 | U28: 2009 | V28: =U28*0.85*0.9 -> 1536.885 | W28: =V28+U28*0.09+99 -> 1816.695 | X28: =U28/T28-1 -> 0.02640908
A29: ='【1】基本信息&审核标准'!$E$2 -> 6-6栋 | B29: 403 | C29: 6-6H | D29: 开间 | E29: =VLOOKUP(D29,'【2】运营中心填-楼栋基准格局定价'!B:H,7,0) -> 1449.8 | F29: 适中 | G29: =VLOOKUP($F$1&F29,定价因子!E:F,2,0) -> 1 | H29: 无 | I29: =VLOOKUP($H$1&H29,定价因子!E:F,2,0) -> 1 | J29: 4F | K29: =VLOOKUP(J29,定价因子!D:F,3,0) -> 1 | L29: 无 | M29: =VLOOKUP($L$1&L29,定价因子!E:F,2,0) -> 1 | N29: 适中 | O29: =VLOOKUP($N$1&N29,定价因子!E:F,2,0) -> 1 | P29: 适中 | Q29: =VLOOKUP($P$1&P29,定价因子!$E:$F,2,0) -> 1 | R29: 1 | S29: =VLOOKUP($R$1&R29,定价因子!$E:$F,2,0) -> 0.91 | T29: =E29*PRODUCT(Q29,S29,O29,M29,K29,I29,G29) -> 1319.318 | U29: 1188 | V29: =U29*0.85*0.9 -> 908.82 | W29: =V29+U29*0.09+99 -> 1114.74 | X29: =U29/T29-1 -> -0.09953476
A30: ='【1】基本信息&审核标准'!$E$2 -> 6-6栋 | B30: 404 | C30: 6-6I | D30: 一居室 | E30: =VLOOKUP(D30,'【2】运营中心填-楼栋基准格局定价'!B:H,7,0) -> 2219.7 | F30: 较狭小 | G30: =VLOOKUP($F$1&F30,定价因子!E:F,2,0) -> 0.95 | H30: 无 | I30: =VLOOKUP($H$1&H30,定价因子!E:F,2,0) -> 1 | J30: 4F | K30: =VLOOKUP(J30,定价因子!D:F,3,0) -> 1 | L30: 无 | M30: =VLOOKUP($L$1&L30,定价因子!E:F,2,0) -> 1 | N30: 适中 | O30: =VLOOKUP($N$1&N30,定价因子!E:F,2,0) -> 1 | P30: 充配（书桌） | Q30: =VLOOKUP($P$1&P30,定价因子!$E:$F,2,0) -> 1.02 | R30: 1 | S30: =VLOOKUP($R$1&R30,定价因子!$E:$F,2,0) -> 0.91 | T30: =E30*PRODUCT(Q30,S30,O30,M30,K30,I30,G30) -> 1957.3093 | U30: 1762 | V30: =U30*0.85*0.9 -> 1347.93 | W30: =V30+U30*0.09+99 -> 1605.51 | X30: =U30/T30-1 -> -0.09978457
A31: ='【1】基本信息&审核标准'!$E$2 -> 6-6栋 | B31: 405 | C31: 6-6J | D31: 开间 | E31: =VLOOKUP(D31,'【2】运营中心填-楼栋基准格局定价'!B:H,7,0) -> 1449.8 | F31: 较狭小 | G31: =VLOOKUP($F$1&F31,定价因子!E:F,2,0) -> 0.95 | H31: 无 | I31: =VLOOKUP($H$1&H31,定价因子!E:F,2,0) -> 1 | J31: 4F | K31: =VLOOKUP(J31,定价因子!D:F,3,0) -> 1 | L31: 无 | M31: =VLOOKUP($L$1&L31,定价因子!E:F,2,0) -> 1 | N31: 适中 | O31: =VLOOKUP($N$1&N31,定价因子!E:F,2,0) -> 1 | P31: 适中 | Q31: =VLOOKUP($P$1&P31,定价因子!$E:$F,2,0) -> 1 | R31: 1 | S31: =VLOOKUP($R$1&R31,定价因子!$E:$F,2,0) -> 0.91 | T31: =E31*PRODUCT(Q31,S31,O31,M31,K31,I31,G31) -> 1253.3521 | U31: 1128 | V31: =U31*0.85*0.9 -> 862.92 | W31: =V31+U31*0.09+99 -> 1063.44 | X31: =U31/T31-1 -> -0.10001348
A32: ='【1】基本信息&审核标准'!$E$2 -> 6-6栋 | B32: 406 | C32: 6-6K | D32: 开间 | E32: =VLOOKUP(D32,'【2】运营中心填-楼栋基准格局定价'!B:H,7,0) -> 1449.8 | F32: 较狭小 | G32: =VLOOKUP($F$1&F32,定价因子!E:F,2,0) -> 0.95 | H32: 无 | I32: =VLOOKUP($H$1&H32,定价因子!E:F,2,0) -> 1 | J32: 4F | K32: =VLOOKUP(J32,定价因子!D:F,3,0) -> 1 | L32: 无 | M32: =VLOOKUP($L$1&L32,定价因子!E:F,2,0) -> 1 | N32: 适中 | O32: =VLOOKUP($N$1&N32,定价因子!E:F,2,0) -> 1 | P32: 适中 | Q32: =VLOOKUP($P$1&P32,定价因子!$E:$F,2,0) -> 1 | R32: 1 | S32: =VLOOKUP($R$1&R32,定价因子!$E:$F,2,0) -> 0.91 | T32: =E32*PRODUCT(Q32,S32,O32,M32,K32,I32,G32) -> 1253.3521 | U32: 1128 | V32: =U32*0.85*0.9 -> 862.92 | W32: =V32+U32*0.09+99 -> 1063.44 | X32: =U32/T32-1 -> -0.10001348
A33: ='【1】基本信息&审核标准'!$E$2 -> 6-6栋 | B33: 407 | C33: 6-6L | D33: 开间 | E33: =VLOOKUP(D33,'【2】运营中心填-楼栋基准格局定价'!B:H,7,0) -> 1449.8 | F33: 适中 | G33: =VLOOKUP($F$1&F33,定价因子!E:F,2,0) -> 1 | H33: 无 | I33: =VLOOKUP($H$1&H33,定价因子!E:F,2,0) -> 1 | J33: 4F | K33: =VLOOKUP(J33,定价因子!D:F,3,0) -> 1 | L33: 无 | M33: =VLOOKUP($L$1&L33,定价因子!E:F,2,0) -> 1 | N33: 充足（单人沙发/餐桌椅） | O33: =VLOOKUP($N$1&N33,定价因子!E:F,2,0) -> 1.03 | P33: 适中 | Q33: =VLOOKUP($P$1&P33,定价因子!$E:$F,2,0) -> 1 | R33: 2 | S33: =VLOOKUP($R$1&R33,定价因子!$E:$F,2,0) -> 0.96 | T33: =E33*PRODUCT(Q33,S33,O33,M33,K33,I33,G33) -> 1433.5622 | U33: 1400 | V33: =U33*0.85*0.9 -> 1071 | W33: =V33+U33*0.09+99 -> 1296 | X33: =U33/T33-1 -> -0.023411777
A34: ='【1】基本信息&审核标准'!$E$2 -> 6-6栋 | B34: 408 | C34: 6-6M | D34: 一居室 | E34: =VLOOKUP(D34,'【2】运营中心填-楼栋基准格局定价'!B:H,7,0) -> 2219.7 | F34: 较狭小 | G34: =VLOOKUP($F$1&F34,定价因子!E:F,2,0) -> 0.95 | H34: 无 | I34: =VLOOKUP($H$1&H34,定价因子!E:F,2,0) -> 1 | J34: 4F | K34: =VLOOKUP(J34,定价因子!D:F,3,0) -> 1 | L34: 无 | M34: =VLOOKUP($L$1&L34,定价因子!E:F,2,0) -> 1 | N34: 适中 | O34: =VLOOKUP($N$1&N34,定价因子!E:F,2,0) -> 1 | P34: 充配（油烟机） | Q34: =VLOOKUP($P$1&P34,定价因子!$E:$F,2,0) -> 1.04 | R34: 4 | S34: =VLOOKUP($R$1&R34,定价因子!$E:$F,2,0) -> 1.03 | T34: =E34*PRODUCT(Q34,S34,O34,M34,K34,I34,G34) -> 2258.8555 | U34: =U26-50 -> 2229 | V34: =U34*0.85*0.9 -> 1705.185 | W34: =V34+U34*0.09+99 -> 2004.795 | X34: =U34/T34-1 -> -0.013217095
A35: ='【1】基本信息&审核标准'!$E$2 -> 6-6栋 | B35: 501 | C35: 6-6F | D35: 一居室 | E35: =VLOOKUP(D35,'【2】运营中心填-楼栋基准格局定价'!B:H,7,0) -> 2219.7 | F35: 适中 | G35: =VLOOKUP($F$1&F35,定价因子!E:F,2,0) -> 1 | H35: 无 | I35: =VLOOKUP($H$1&H35,定价因子!E:F,2,0) -> 1 | J35: 5F | K35: =VLOOKUP(J35,定价因子!D:F,3,0) -> 0.99 | L35: 无 | M35: =VLOOKUP($L$1&L35,定价因子!E:F,2,0) -> 1 | N35: 适中 | O35: =VLOOKUP($N$1&N35,定价因子!E:F,2,0) -> 1 | P35: 充配（书桌） | Q35: =VLOOKUP($P$1&P35,定价因子!$E:$F,2,0) -> 1.02 | R35: 1 | S35: =VLOOKUP($R$1&R35,定价因子!$E:$F,2,0) -> 0.91 | T35: =E35*PRODUCT(Q35,S35,O35,M35,K35,I35,G35) -> 2039.7223 | U35: 2029 | V35: =U35*0.85*0.9 -> 1552.185 | W35: =V35+U35*0.09+99 -> 1833.795 | X35: =U35/T35-1 -> -0.0052567375
